[DEBUG] 2017-05-24 05:49:54,443 | /Users/user/Documents/ERPNext-22-05-2017/frappe-bench/apps/frappe/frappe/utils/scheduler.py:
Site: site.local-development
Queued events for site site.local-development
[ERROR] 2017-05-24 05:49:54,456 | /Users/user/Documents/ERPNext-22-05-2017/frappe-bench/apps/frappe/frappe/utils/scheduler.py:
Site: site1.local
Exception in Enqueue Events for Site site1.local
Traceback (most recent call last):
  File "/Users/user/Documents/ERPNext-22-05-2017/frappe-bench/apps/frappe/frappe/utils/scheduler.py", line 63, in enqueue_events_for_site
    if is_scheduler_disabled():
  File "/Users/user/Documents/ERPNext-22-05-2017/frappe-bench/apps/frappe/frappe/utils/scheduler.py", line 207, in is_scheduler_disabled
    return not frappe.utils.cint(frappe.db.get_single_value("System Settings", "enable_scheduler"))
  File "/Users/user/Documents/ERPNext-22-05-2017/frappe-bench/apps/frappe/frappe/database.py", line 554, in get_single_value
    tabSingles where doctype=%s and field=%s""", (doctype, fieldname))
  File "/Users/user/Documents/ERPNext-22-05-2017/frappe-bench/apps/frappe/frappe/database.py", line 107, in sql
    self.connect()
  File "/Users/user/Documents/ERPNext-22-05-2017/frappe-bench/apps/frappe/frappe/database.py", line 53, in connect
    use_unicode=True, charset='utf8mb4')
  File "/Users/user/Documents/ERPNext-22-05-2017/frappe-bench/env/lib/python2.7/site-packages/MySQLdb/__init__.py", line 81, in Connect
    return Connection(*args, **kwargs)
  File "/Users/user/Documents/ERPNext-22-05-2017/frappe-bench/env/lib/python2.7/site-packages/MySQLdb/connections.py", line 193, in __init__
    super(Connection, self).__init__(*args, **kwargs2)
OperationalError: (1045, "Access denied for user '1bd3e0294da19198'@'localhost' (using password: YES)")

[DEBUG] 2017-05-24 05:53:54,552 | /Users/user/Documents/ERPNext-22-05-2017/frappe-bench/apps/frappe/frappe/utils/scheduler.py:
Site: site.local-development
Queued events for site site.local-development
[ERROR] 2017-05-24 05:53:54,555 | /Users/user/Documents/ERPNext-22-05-2017/frappe-bench/apps/frappe/frappe/utils/scheduler.py:
Site: site1.local
Exception in Enqueue Events for Site site1.local
Traceback (most recent call last):
  File "/Users/user/Documents/ERPNext-22-05-2017/frappe-bench/apps/frappe/frappe/utils/scheduler.py", line 63, in enqueue_events_for_site
    if is_scheduler_disabled():
  File "/Users/user/Documents/ERPNext-22-05-2017/frappe-bench/apps/frappe/frappe/utils/scheduler.py", line 207, in is_scheduler_disabled
    return not frappe.utils.cint(frappe.db.get_single_value("System Settings", "enable_scheduler"))
  File "/Users/user/Documents/ERPNext-22-05-2017/frappe-bench/apps/frappe/frappe/database.py", line 554, in get_single_value
    tabSingles where doctype=%s and field=%s""", (doctype, fieldname))
  File "/Users/user/Documents/ERPNext-22-05-2017/frappe-bench/apps/frappe/frappe/database.py", line 107, in sql
    self.connect()
  File "/Users/user/Documents/ERPNext-22-05-2017/frappe-bench/apps/frappe/frappe/database.py", line 53, in connect
    use_unicode=True, charset='utf8mb4')
  File "/Users/user/Documents/ERPNext-22-05-2017/frappe-bench/env/lib/python2.7/site-packages/MySQLdb/__init__.py", line 81, in Connect
    return Connection(*args, **kwargs)
  File "/Users/user/Documents/ERPNext-22-05-2017/frappe-bench/env/lib/python2.7/site-packages/MySQLdb/connections.py", line 193, in __init__
    super(Connection, self).__init__(*args, **kwargs2)
OperationalError: (1045, "Access denied for user '1bd3e0294da19198'@'localhost' (using password: YES)")

[DEBUG] 2017-05-24 05:57:55,384 | /Users/user/Documents/ERPNext-22-05-2017/frappe-bench/apps/frappe/frappe/utils/scheduler.py:
Site: site.local-development
Queued events for site site.local-development
[ERROR] 2017-05-24 05:57:55,385 | /Users/user/Documents/ERPNext-22-05-2017/frappe-bench/apps/frappe/frappe/utils/scheduler.py:
Site: site1.local
Exception in Enqueue Events for Site site1.local
Traceback (most recent call last):
  File "/Users/user/Documents/ERPNext-22-05-2017/frappe-bench/apps/frappe/frappe/utils/scheduler.py", line 63, in enqueue_events_for_site
    if is_scheduler_disabled():
  File "/Users/user/Documents/ERPNext-22-05-2017/frappe-bench/apps/frappe/frappe/utils/scheduler.py", line 207, in is_scheduler_disabled
    return not frappe.utils.cint(frappe.db.get_single_value("System Settings", "enable_scheduler"))
  File "/Users/user/Documents/ERPNext-22-05-2017/frappe-bench/apps/frappe/frappe/database.py", line 554, in get_single_value
    tabSingles where doctype=%s and field=%s""", (doctype, fieldname))
  File "/Users/user/Documents/ERPNext-22-05-2017/frappe-bench/apps/frappe/frappe/database.py", line 107, in sql
    self.connect()
  File "/Users/user/Documents/ERPNext-22-05-2017/frappe-bench/apps/frappe/frappe/database.py", line 53, in connect
    use_unicode=True, charset='utf8mb4')
  File "/Users/user/Documents/ERPNext-22-05-2017/frappe-bench/env/lib/python2.7/site-packages/MySQLdb/__init__.py", line 81, in Connect
    return Connection(*args, **kwargs)
  File "/Users/user/Documents/ERPNext-22-05-2017/frappe-bench/env/lib/python2.7/site-packages/MySQLdb/connections.py", line 193, in __init__
    super(Connection, self).__init__(*args, **kwargs2)
OperationalError: (1045, "Access denied for user '1bd3e0294da19198'@'localhost' (using password: YES)")

[DEBUG] 2017-05-24 06:01:56,189 | /Users/user/Documents/ERPNext-22-05-2017/frappe-bench/apps/frappe/frappe/utils/scheduler.py:
Site: site.local-development
Queued events for site site.local-development
[ERROR] 2017-05-24 06:01:56,191 | /Users/user/Documents/ERPNext-22-05-2017/frappe-bench/apps/frappe/frappe/utils/scheduler.py:
Site: site1.local
Exception in Enqueue Events for Site site1.local
Traceback (most recent call last):
  File "/Users/user/Documents/ERPNext-22-05-2017/frappe-bench/apps/frappe/frappe/utils/scheduler.py", line 63, in enqueue_events_for_site
    if is_scheduler_disabled():
  File "/Users/user/Documents/ERPNext-22-05-2017/frappe-bench/apps/frappe/frappe/utils/scheduler.py", line 207, in is_scheduler_disabled
    return not frappe.utils.cint(frappe.db.get_single_value("System Settings", "enable_scheduler"))
  File "/Users/user/Documents/ERPNext-22-05-2017/frappe-bench/apps/frappe/frappe/database.py", line 554, in get_single_value
    tabSingles where doctype=%s and field=%s""", (doctype, fieldname))
  File "/Users/user/Documents/ERPNext-22-05-2017/frappe-bench/apps/frappe/frappe/database.py", line 107, in sql
    self.connect()
  File "/Users/user/Documents/ERPNext-22-05-2017/frappe-bench/apps/frappe/frappe/database.py", line 53, in connect
    use_unicode=True, charset='utf8mb4')
  File "/Users/user/Documents/ERPNext-22-05-2017/frappe-bench/env/lib/python2.7/site-packages/MySQLdb/__init__.py", line 81, in Connect
    return Connection(*args, **kwargs)
  File "/Users/user/Documents/ERPNext-22-05-2017/frappe-bench/env/lib/python2.7/site-packages/MySQLdb/connections.py", line 193, in __init__
    super(Connection, self).__init__(*args, **kwargs2)
OperationalError: (1045, "Access denied for user '1bd3e0294da19198'@'localhost' (using password: YES)")

[DEBUG] 2017-05-24 06:06:30,087 | /Users/user/Documents/ERPNext-22-05-2017/frappe-bench/apps/frappe/frappe/utils/scheduler.py:
Site: site.local-development
Queued events for site site.local-development
[ERROR] 2017-05-24 06:06:30,090 | /Users/user/Documents/ERPNext-22-05-2017/frappe-bench/apps/frappe/frappe/utils/scheduler.py:
Site: site1.local
Exception in Enqueue Events for Site site1.local
Traceback (most recent call last):
  File "/Users/user/Documents/ERPNext-22-05-2017/frappe-bench/apps/frappe/frappe/utils/scheduler.py", line 63, in enqueue_events_for_site
    if is_scheduler_disabled():
  File "/Users/user/Documents/ERPNext-22-05-2017/frappe-bench/apps/frappe/frappe/utils/scheduler.py", line 207, in is_scheduler_disabled
    return not frappe.utils.cint(frappe.db.get_single_value("System Settings", "enable_scheduler"))
  File "/Users/user/Documents/ERPNext-22-05-2017/frappe-bench/apps/frappe/frappe/database.py", line 554, in get_single_value
    tabSingles where doctype=%s and field=%s""", (doctype, fieldname))
  File "/Users/user/Documents/ERPNext-22-05-2017/frappe-bench/apps/frappe/frappe/database.py", line 107, in sql
    self.connect()
  File "/Users/user/Documents/ERPNext-22-05-2017/frappe-bench/apps/frappe/frappe/database.py", line 53, in connect
    use_unicode=True, charset='utf8mb4')
  File "/Users/user/Documents/ERPNext-22-05-2017/frappe-bench/env/lib/python2.7/site-packages/MySQLdb/__init__.py", line 81, in Connect
    return Connection(*args, **kwargs)
  File "/Users/user/Documents/ERPNext-22-05-2017/frappe-bench/env/lib/python2.7/site-packages/MySQLdb/connections.py", line 193, in __init__
    super(Connection, self).__init__(*args, **kwargs2)
OperationalError: (1045, "Access denied for user '1bd3e0294da19198'@'localhost' (using password: YES)")

[DEBUG] 2017-05-24 06:10:30,472 | /Users/user/Documents/ERPNext-22-05-2017/frappe-bench/apps/frappe/frappe/utils/scheduler.py:
Site: site.local-development
Queued events for site site.local-development
[ERROR] 2017-05-24 06:10:30,473 | /Users/user/Documents/ERPNext-22-05-2017/frappe-bench/apps/frappe/frappe/utils/scheduler.py:
Site: site1.local
Exception in Enqueue Events for Site site1.local
Traceback (most recent call last):
  File "/Users/user/Documents/ERPNext-22-05-2017/frappe-bench/apps/frappe/frappe/utils/scheduler.py", line 63, in enqueue_events_for_site
    if is_scheduler_disabled():
  File "/Users/user/Documents/ERPNext-22-05-2017/frappe-bench/apps/frappe/frappe/utils/scheduler.py", line 207, in is_scheduler_disabled
    return not frappe.utils.cint(frappe.db.get_single_value("System Settings", "enable_scheduler"))
  File "/Users/user/Documents/ERPNext-22-05-2017/frappe-bench/apps/frappe/frappe/database.py", line 554, in get_single_value
    tabSingles where doctype=%s and field=%s""", (doctype, fieldname))
  File "/Users/user/Documents/ERPNext-22-05-2017/frappe-bench/apps/frappe/frappe/database.py", line 107, in sql
    self.connect()
  File "/Users/user/Documents/ERPNext-22-05-2017/frappe-bench/apps/frappe/frappe/database.py", line 53, in connect
    use_unicode=True, charset='utf8mb4')
  File "/Users/user/Documents/ERPNext-22-05-2017/frappe-bench/env/lib/python2.7/site-packages/MySQLdb/__init__.py", line 81, in Connect
    return Connection(*args, **kwargs)
  File "/Users/user/Documents/ERPNext-22-05-2017/frappe-bench/env/lib/python2.7/site-packages/MySQLdb/connections.py", line 193, in __init__
    super(Connection, self).__init__(*args, **kwargs2)
OperationalError: (1045, "Access denied for user '1bd3e0294da19198'@'localhost' (using password: YES)")

[DEBUG] 2017-05-24 06:14:31,028 | /Users/user/Documents/ERPNext-22-05-2017/frappe-bench/apps/frappe/frappe/utils/scheduler.py:
Site: site.local-development
Queued events for site site.local-development
[ERROR] 2017-05-24 06:14:31,030 | /Users/user/Documents/ERPNext-22-05-2017/frappe-bench/apps/frappe/frappe/utils/scheduler.py:
Site: site1.local
Exception in Enqueue Events for Site site1.local
Traceback (most recent call last):
  File "/Users/user/Documents/ERPNext-22-05-2017/frappe-bench/apps/frappe/frappe/utils/scheduler.py", line 63, in enqueue_events_for_site
    if is_scheduler_disabled():
  File "/Users/user/Documents/ERPNext-22-05-2017/frappe-bench/apps/frappe/frappe/utils/scheduler.py", line 207, in is_scheduler_disabled
    return not frappe.utils.cint(frappe.db.get_single_value("System Settings", "enable_scheduler"))
  File "/Users/user/Documents/ERPNext-22-05-2017/frappe-bench/apps/frappe/frappe/database.py", line 554, in get_single_value
    tabSingles where doctype=%s and field=%s""", (doctype, fieldname))
  File "/Users/user/Documents/ERPNext-22-05-2017/frappe-bench/apps/frappe/frappe/database.py", line 107, in sql
    self.connect()
  File "/Users/user/Documents/ERPNext-22-05-2017/frappe-bench/apps/frappe/frappe/database.py", line 53, in connect
    use_unicode=True, charset='utf8mb4')
  File "/Users/user/Documents/ERPNext-22-05-2017/frappe-bench/env/lib/python2.7/site-packages/MySQLdb/__init__.py", line 81, in Connect
    return Connection(*args, **kwargs)
  File "/Users/user/Documents/ERPNext-22-05-2017/frappe-bench/env/lib/python2.7/site-packages/MySQLdb/connections.py", line 193, in __init__
    super(Connection, self).__init__(*args, **kwargs2)
OperationalError: (1045, "Access denied for user '1bd3e0294da19198'@'localhost' (using password: YES)")

[DEBUG] 2017-05-24 06:18:31,330 | /Users/user/Documents/ERPNext-22-05-2017/frappe-bench/apps/frappe/frappe/utils/scheduler.py:
Site: site.local-development
Queued events for site site.local-development
[ERROR] 2017-05-24 06:18:31,331 | /Users/user/Documents/ERPNext-22-05-2017/frappe-bench/apps/frappe/frappe/utils/scheduler.py:
Site: site1.local
Exception in Enqueue Events for Site site1.local
Traceback (most recent call last):
  File "/Users/user/Documents/ERPNext-22-05-2017/frappe-bench/apps/frappe/frappe/utils/scheduler.py", line 63, in enqueue_events_for_site
    if is_scheduler_disabled():
  File "/Users/user/Documents/ERPNext-22-05-2017/frappe-bench/apps/frappe/frappe/utils/scheduler.py", line 207, in is_scheduler_disabled
    return not frappe.utils.cint(frappe.db.get_single_value("System Settings", "enable_scheduler"))
  File "/Users/user/Documents/ERPNext-22-05-2017/frappe-bench/apps/frappe/frappe/database.py", line 554, in get_single_value
    tabSingles where doctype=%s and field=%s""", (doctype, fieldname))
  File "/Users/user/Documents/ERPNext-22-05-2017/frappe-bench/apps/frappe/frappe/database.py", line 107, in sql
    self.connect()
  File "/Users/user/Documents/ERPNext-22-05-2017/frappe-bench/apps/frappe/frappe/database.py", line 53, in connect
    use_unicode=True, charset='utf8mb4')
  File "/Users/user/Documents/ERPNext-22-05-2017/frappe-bench/env/lib/python2.7/site-packages/MySQLdb/__init__.py", line 81, in Connect
    return Connection(*args, **kwargs)
  File "/Users/user/Documents/ERPNext-22-05-2017/frappe-bench/env/lib/python2.7/site-packages/MySQLdb/connections.py", line 193, in __init__
    super(Connection, self).__init__(*args, **kwargs2)
OperationalError: (1045, "Access denied for user '1bd3e0294da19198'@'localhost' (using password: YES)")

[DEBUG] 2017-05-24 06:22:32,189 | /Users/user/Documents/ERPNext-22-05-2017/frappe-bench/apps/frappe/frappe/utils/scheduler.py:
Site: site.local-development
Queued events for site site.local-development
[ERROR] 2017-05-24 06:22:32,191 | /Users/user/Documents/ERPNext-22-05-2017/frappe-bench/apps/frappe/frappe/utils/scheduler.py:
Site: site1.local
Exception in Enqueue Events for Site site1.local
Traceback (most recent call last):
  File "/Users/user/Documents/ERPNext-22-05-2017/frappe-bench/apps/frappe/frappe/utils/scheduler.py", line 63, in enqueue_events_for_site
    if is_scheduler_disabled():
  File "/Users/user/Documents/ERPNext-22-05-2017/frappe-bench/apps/frappe/frappe/utils/scheduler.py", line 207, in is_scheduler_disabled
    return not frappe.utils.cint(frappe.db.get_single_value("System Settings", "enable_scheduler"))
  File "/Users/user/Documents/ERPNext-22-05-2017/frappe-bench/apps/frappe/frappe/database.py", line 554, in get_single_value
    tabSingles where doctype=%s and field=%s""", (doctype, fieldname))
  File "/Users/user/Documents/ERPNext-22-05-2017/frappe-bench/apps/frappe/frappe/database.py", line 107, in sql
    self.connect()
  File "/Users/user/Documents/ERPNext-22-05-2017/frappe-bench/apps/frappe/frappe/database.py", line 53, in connect
    use_unicode=True, charset='utf8mb4')
  File "/Users/user/Documents/ERPNext-22-05-2017/frappe-bench/env/lib/python2.7/site-packages/MySQLdb/__init__.py", line 81, in Connect
    return Connection(*args, **kwargs)
  File "/Users/user/Documents/ERPNext-22-05-2017/frappe-bench/env/lib/python2.7/site-packages/MySQLdb/connections.py", line 193, in __init__
    super(Connection, self).__init__(*args, **kwargs2)
OperationalError: (1045, "Access denied for user '1bd3e0294da19198'@'localhost' (using password: YES)")

[DEBUG] 2017-05-24 06:26:32,261 | /Users/user/Documents/ERPNext-22-05-2017/frappe-bench/apps/frappe/frappe/utils/scheduler.py:
Site: site.local-development
Queued events for site site.local-development
[ERROR] 2017-05-24 06:26:32,263 | /Users/user/Documents/ERPNext-22-05-2017/frappe-bench/apps/frappe/frappe/utils/scheduler.py:
Site: site1.local
Exception in Enqueue Events for Site site1.local
Traceback (most recent call last):
  File "/Users/user/Documents/ERPNext-22-05-2017/frappe-bench/apps/frappe/frappe/utils/scheduler.py", line 63, in enqueue_events_for_site
    if is_scheduler_disabled():
  File "/Users/user/Documents/ERPNext-22-05-2017/frappe-bench/apps/frappe/frappe/utils/scheduler.py", line 207, in is_scheduler_disabled
    return not frappe.utils.cint(frappe.db.get_single_value("System Settings", "enable_scheduler"))
  File "/Users/user/Documents/ERPNext-22-05-2017/frappe-bench/apps/frappe/frappe/database.py", line 554, in get_single_value
    tabSingles where doctype=%s and field=%s""", (doctype, fieldname))
  File "/Users/user/Documents/ERPNext-22-05-2017/frappe-bench/apps/frappe/frappe/database.py", line 107, in sql
    self.connect()
  File "/Users/user/Documents/ERPNext-22-05-2017/frappe-bench/apps/frappe/frappe/database.py", line 53, in connect
    use_unicode=True, charset='utf8mb4')
  File "/Users/user/Documents/ERPNext-22-05-2017/frappe-bench/env/lib/python2.7/site-packages/MySQLdb/__init__.py", line 81, in Connect
    return Connection(*args, **kwargs)
  File "/Users/user/Documents/ERPNext-22-05-2017/frappe-bench/env/lib/python2.7/site-packages/MySQLdb/connections.py", line 193, in __init__
    super(Connection, self).__init__(*args, **kwargs2)
OperationalError: (1045, "Access denied for user '1bd3e0294da19198'@'localhost' (using password: YES)")

[DEBUG] 2017-05-24 06:30:33,199 | /Users/user/Documents/ERPNext-22-05-2017/frappe-bench/apps/frappe/frappe/utils/scheduler.py:
Site: site.local-development
Queued events for site site.local-development
[ERROR] 2017-05-24 06:30:33,201 | /Users/user/Documents/ERPNext-22-05-2017/frappe-bench/apps/frappe/frappe/utils/scheduler.py:
Site: site1.local
Exception in Enqueue Events for Site site1.local
Traceback (most recent call last):
  File "/Users/user/Documents/ERPNext-22-05-2017/frappe-bench/apps/frappe/frappe/utils/scheduler.py", line 63, in enqueue_events_for_site
    if is_scheduler_disabled():
  File "/Users/user/Documents/ERPNext-22-05-2017/frappe-bench/apps/frappe/frappe/utils/scheduler.py", line 207, in is_scheduler_disabled
    return not frappe.utils.cint(frappe.db.get_single_value("System Settings", "enable_scheduler"))
  File "/Users/user/Documents/ERPNext-22-05-2017/frappe-bench/apps/frappe/frappe/database.py", line 554, in get_single_value
    tabSingles where doctype=%s and field=%s""", (doctype, fieldname))
  File "/Users/user/Documents/ERPNext-22-05-2017/frappe-bench/apps/frappe/frappe/database.py", line 107, in sql
    self.connect()
  File "/Users/user/Documents/ERPNext-22-05-2017/frappe-bench/apps/frappe/frappe/database.py", line 53, in connect
    use_unicode=True, charset='utf8mb4')
  File "/Users/user/Documents/ERPNext-22-05-2017/frappe-bench/env/lib/python2.7/site-packages/MySQLdb/__init__.py", line 81, in Connect
    return Connection(*args, **kwargs)
  File "/Users/user/Documents/ERPNext-22-05-2017/frappe-bench/env/lib/python2.7/site-packages/MySQLdb/connections.py", line 193, in __init__
    super(Connection, self).__init__(*args, **kwargs2)
OperationalError: (1045, "Access denied for user '1bd3e0294da19198'@'localhost' (using password: YES)")

[DEBUG] 2017-05-24 06:34:33,492 | /Users/user/Documents/ERPNext-22-05-2017/frappe-bench/apps/frappe/frappe/utils/scheduler.py:
Site: site.local-development
Queued events for site site.local-development
[ERROR] 2017-05-24 06:34:33,494 | /Users/user/Documents/ERPNext-22-05-2017/frappe-bench/apps/frappe/frappe/utils/scheduler.py:
Site: site1.local
Exception in Enqueue Events for Site site1.local
Traceback (most recent call last):
  File "/Users/user/Documents/ERPNext-22-05-2017/frappe-bench/apps/frappe/frappe/utils/scheduler.py", line 63, in enqueue_events_for_site
    if is_scheduler_disabled():
  File "/Users/user/Documents/ERPNext-22-05-2017/frappe-bench/apps/frappe/frappe/utils/scheduler.py", line 207, in is_scheduler_disabled
    return not frappe.utils.cint(frappe.db.get_single_value("System Settings", "enable_scheduler"))
  File "/Users/user/Documents/ERPNext-22-05-2017/frappe-bench/apps/frappe/frappe/database.py", line 554, in get_single_value
    tabSingles where doctype=%s and field=%s""", (doctype, fieldname))
  File "/Users/user/Documents/ERPNext-22-05-2017/frappe-bench/apps/frappe/frappe/database.py", line 107, in sql
    self.connect()
  File "/Users/user/Documents/ERPNext-22-05-2017/frappe-bench/apps/frappe/frappe/database.py", line 53, in connect
    use_unicode=True, charset='utf8mb4')
  File "/Users/user/Documents/ERPNext-22-05-2017/frappe-bench/env/lib/python2.7/site-packages/MySQLdb/__init__.py", line 81, in Connect
    return Connection(*args, **kwargs)
  File "/Users/user/Documents/ERPNext-22-05-2017/frappe-bench/env/lib/python2.7/site-packages/MySQLdb/connections.py", line 193, in __init__
    super(Connection, self).__init__(*args, **kwargs2)
OperationalError: (1045, "Access denied for user '1bd3e0294da19198'@'localhost' (using password: YES)")

[DEBUG] 2017-05-24 06:38:34,206 | /Users/user/Documents/ERPNext-22-05-2017/frappe-bench/apps/frappe/frappe/utils/scheduler.py:
Site: site.local-development
Queued events for site site.local-development
[ERROR] 2017-05-24 06:38:34,208 | /Users/user/Documents/ERPNext-22-05-2017/frappe-bench/apps/frappe/frappe/utils/scheduler.py:
Site: site1.local
Exception in Enqueue Events for Site site1.local
Traceback (most recent call last):
  File "/Users/user/Documents/ERPNext-22-05-2017/frappe-bench/apps/frappe/frappe/utils/scheduler.py", line 63, in enqueue_events_for_site
    if is_scheduler_disabled():
  File "/Users/user/Documents/ERPNext-22-05-2017/frappe-bench/apps/frappe/frappe/utils/scheduler.py", line 207, in is_scheduler_disabled
    return not frappe.utils.cint(frappe.db.get_single_value("System Settings", "enable_scheduler"))
  File "/Users/user/Documents/ERPNext-22-05-2017/frappe-bench/apps/frappe/frappe/database.py", line 554, in get_single_value
    tabSingles where doctype=%s and field=%s""", (doctype, fieldname))
  File "/Users/user/Documents/ERPNext-22-05-2017/frappe-bench/apps/frappe/frappe/database.py", line 107, in sql
    self.connect()
  File "/Users/user/Documents/ERPNext-22-05-2017/frappe-bench/apps/frappe/frappe/database.py", line 53, in connect
    use_unicode=True, charset='utf8mb4')
  File "/Users/user/Documents/ERPNext-22-05-2017/frappe-bench/env/lib/python2.7/site-packages/MySQLdb/__init__.py", line 81, in Connect
    return Connection(*args, **kwargs)
  File "/Users/user/Documents/ERPNext-22-05-2017/frappe-bench/env/lib/python2.7/site-packages/MySQLdb/connections.py", line 193, in __init__
    super(Connection, self).__init__(*args, **kwargs2)
OperationalError: (1045, "Access denied for user '1bd3e0294da19198'@'localhost' (using password: YES)")

[DEBUG] 2017-05-24 06:42:34,455 | /Users/user/Documents/ERPNext-22-05-2017/frappe-bench/apps/frappe/frappe/utils/scheduler.py:
Site: site.local-development
Queued events for site site.local-development
[ERROR] 2017-05-24 06:42:34,457 | /Users/user/Documents/ERPNext-22-05-2017/frappe-bench/apps/frappe/frappe/utils/scheduler.py:
Site: site1.local
Exception in Enqueue Events for Site site1.local
Traceback (most recent call last):
  File "/Users/user/Documents/ERPNext-22-05-2017/frappe-bench/apps/frappe/frappe/utils/scheduler.py", line 63, in enqueue_events_for_site
    if is_scheduler_disabled():
  File "/Users/user/Documents/ERPNext-22-05-2017/frappe-bench/apps/frappe/frappe/utils/scheduler.py", line 207, in is_scheduler_disabled
    return not frappe.utils.cint(frappe.db.get_single_value("System Settings", "enable_scheduler"))
  File "/Users/user/Documents/ERPNext-22-05-2017/frappe-bench/apps/frappe/frappe/database.py", line 554, in get_single_value
    tabSingles where doctype=%s and field=%s""", (doctype, fieldname))
  File "/Users/user/Documents/ERPNext-22-05-2017/frappe-bench/apps/frappe/frappe/database.py", line 107, in sql
    self.connect()
  File "/Users/user/Documents/ERPNext-22-05-2017/frappe-bench/apps/frappe/frappe/database.py", line 53, in connect
    use_unicode=True, charset='utf8mb4')
  File "/Users/user/Documents/ERPNext-22-05-2017/frappe-bench/env/lib/python2.7/site-packages/MySQLdb/__init__.py", line 81, in Connect
    return Connection(*args, **kwargs)
  File "/Users/user/Documents/ERPNext-22-05-2017/frappe-bench/env/lib/python2.7/site-packages/MySQLdb/connections.py", line 193, in __init__
    super(Connection, self).__init__(*args, **kwargs2)
OperationalError: (1045, "Access denied for user '1bd3e0294da19198'@'localhost' (using password: YES)")

[DEBUG] 2017-05-24 06:46:35,027 | /Users/user/Documents/ERPNext-22-05-2017/frappe-bench/apps/frappe/frappe/utils/scheduler.py:
Site: site.local-development
Queued events for site site.local-development
[ERROR] 2017-05-24 06:46:35,029 | /Users/user/Documents/ERPNext-22-05-2017/frappe-bench/apps/frappe/frappe/utils/scheduler.py:
Site: site1.local
Exception in Enqueue Events for Site site1.local
Traceback (most recent call last):
  File "/Users/user/Documents/ERPNext-22-05-2017/frappe-bench/apps/frappe/frappe/utils/scheduler.py", line 63, in enqueue_events_for_site
    if is_scheduler_disabled():
  File "/Users/user/Documents/ERPNext-22-05-2017/frappe-bench/apps/frappe/frappe/utils/scheduler.py", line 207, in is_scheduler_disabled
    return not frappe.utils.cint(frappe.db.get_single_value("System Settings", "enable_scheduler"))
  File "/Users/user/Documents/ERPNext-22-05-2017/frappe-bench/apps/frappe/frappe/database.py", line 554, in get_single_value
    tabSingles where doctype=%s and field=%s""", (doctype, fieldname))
  File "/Users/user/Documents/ERPNext-22-05-2017/frappe-bench/apps/frappe/frappe/database.py", line 107, in sql
    self.connect()
  File "/Users/user/Documents/ERPNext-22-05-2017/frappe-bench/apps/frappe/frappe/database.py", line 53, in connect
    use_unicode=True, charset='utf8mb4')
  File "/Users/user/Documents/ERPNext-22-05-2017/frappe-bench/env/lib/python2.7/site-packages/MySQLdb/__init__.py", line 81, in Connect
    return Connection(*args, **kwargs)
  File "/Users/user/Documents/ERPNext-22-05-2017/frappe-bench/env/lib/python2.7/site-packages/MySQLdb/connections.py", line 193, in __init__
    super(Connection, self).__init__(*args, **kwargs2)
OperationalError: (1045, "Access denied for user '1bd3e0294da19198'@'localhost' (using password: YES)")

[DEBUG] 2017-05-24 06:50:35,514 | /Users/user/Documents/ERPNext-22-05-2017/frappe-bench/apps/frappe/frappe/utils/scheduler.py:
Site: site.local-development
Queued events for site site.local-development
[ERROR] 2017-05-24 06:50:35,516 | /Users/user/Documents/ERPNext-22-05-2017/frappe-bench/apps/frappe/frappe/utils/scheduler.py:
Site: site1.local
Exception in Enqueue Events for Site site1.local
Traceback (most recent call last):
  File "/Users/user/Documents/ERPNext-22-05-2017/frappe-bench/apps/frappe/frappe/utils/scheduler.py", line 63, in enqueue_events_for_site
    if is_scheduler_disabled():
  File "/Users/user/Documents/ERPNext-22-05-2017/frappe-bench/apps/frappe/frappe/utils/scheduler.py", line 207, in is_scheduler_disabled
    return not frappe.utils.cint(frappe.db.get_single_value("System Settings", "enable_scheduler"))
  File "/Users/user/Documents/ERPNext-22-05-2017/frappe-bench/apps/frappe/frappe/database.py", line 554, in get_single_value
    tabSingles where doctype=%s and field=%s""", (doctype, fieldname))
  File "/Users/user/Documents/ERPNext-22-05-2017/frappe-bench/apps/frappe/frappe/database.py", line 107, in sql
    self.connect()
  File "/Users/user/Documents/ERPNext-22-05-2017/frappe-bench/apps/frappe/frappe/database.py", line 53, in connect
    use_unicode=True, charset='utf8mb4')
  File "/Users/user/Documents/ERPNext-22-05-2017/frappe-bench/env/lib/python2.7/site-packages/MySQLdb/__init__.py", line 81, in Connect
    return Connection(*args, **kwargs)
  File "/Users/user/Documents/ERPNext-22-05-2017/frappe-bench/env/lib/python2.7/site-packages/MySQLdb/connections.py", line 193, in __init__
    super(Connection, self).__init__(*args, **kwargs2)
OperationalError: (1045, "Access denied for user '1bd3e0294da19198'@'localhost' (using password: YES)")

[DEBUG] 2017-05-24 06:54:36,219 | /Users/user/Documents/ERPNext-22-05-2017/frappe-bench/apps/frappe/frappe/utils/scheduler.py:
Site: site.local-development
Queued events for site site.local-development
[ERROR] 2017-05-24 06:54:36,221 | /Users/user/Documents/ERPNext-22-05-2017/frappe-bench/apps/frappe/frappe/utils/scheduler.py:
Site: site1.local
Exception in Enqueue Events for Site site1.local
Traceback (most recent call last):
  File "/Users/user/Documents/ERPNext-22-05-2017/frappe-bench/apps/frappe/frappe/utils/scheduler.py", line 63, in enqueue_events_for_site
    if is_scheduler_disabled():
  File "/Users/user/Documents/ERPNext-22-05-2017/frappe-bench/apps/frappe/frappe/utils/scheduler.py", line 207, in is_scheduler_disabled
    return not frappe.utils.cint(frappe.db.get_single_value("System Settings", "enable_scheduler"))
  File "/Users/user/Documents/ERPNext-22-05-2017/frappe-bench/apps/frappe/frappe/database.py", line 554, in get_single_value
    tabSingles where doctype=%s and field=%s""", (doctype, fieldname))
  File "/Users/user/Documents/ERPNext-22-05-2017/frappe-bench/apps/frappe/frappe/database.py", line 107, in sql
    self.connect()
  File "/Users/user/Documents/ERPNext-22-05-2017/frappe-bench/apps/frappe/frappe/database.py", line 53, in connect
    use_unicode=True, charset='utf8mb4')
  File "/Users/user/Documents/ERPNext-22-05-2017/frappe-bench/env/lib/python2.7/site-packages/MySQLdb/__init__.py", line 81, in Connect
    return Connection(*args, **kwargs)
  File "/Users/user/Documents/ERPNext-22-05-2017/frappe-bench/env/lib/python2.7/site-packages/MySQLdb/connections.py", line 193, in __init__
    super(Connection, self).__init__(*args, **kwargs2)
OperationalError: (1045, "Access denied for user '1bd3e0294da19198'@'localhost' (using password: YES)")

[DEBUG] 2017-05-24 06:58:36,417 | /Users/user/Documents/ERPNext-22-05-2017/frappe-bench/apps/frappe/frappe/utils/scheduler.py:
Site: site.local-development
Queued events for site site.local-development
[ERROR] 2017-05-24 06:58:36,419 | /Users/user/Documents/ERPNext-22-05-2017/frappe-bench/apps/frappe/frappe/utils/scheduler.py:
Site: site1.local
Exception in Enqueue Events for Site site1.local
Traceback (most recent call last):
  File "/Users/user/Documents/ERPNext-22-05-2017/frappe-bench/apps/frappe/frappe/utils/scheduler.py", line 63, in enqueue_events_for_site
    if is_scheduler_disabled():
  File "/Users/user/Documents/ERPNext-22-05-2017/frappe-bench/apps/frappe/frappe/utils/scheduler.py", line 207, in is_scheduler_disabled
    return not frappe.utils.cint(frappe.db.get_single_value("System Settings", "enable_scheduler"))
  File "/Users/user/Documents/ERPNext-22-05-2017/frappe-bench/apps/frappe/frappe/database.py", line 554, in get_single_value
    tabSingles where doctype=%s and field=%s""", (doctype, fieldname))
  File "/Users/user/Documents/ERPNext-22-05-2017/frappe-bench/apps/frappe/frappe/database.py", line 107, in sql
    self.connect()
  File "/Users/user/Documents/ERPNext-22-05-2017/frappe-bench/apps/frappe/frappe/database.py", line 53, in connect
    use_unicode=True, charset='utf8mb4')
  File "/Users/user/Documents/ERPNext-22-05-2017/frappe-bench/env/lib/python2.7/site-packages/MySQLdb/__init__.py", line 81, in Connect
    return Connection(*args, **kwargs)
  File "/Users/user/Documents/ERPNext-22-05-2017/frappe-bench/env/lib/python2.7/site-packages/MySQLdb/connections.py", line 193, in __init__
    super(Connection, self).__init__(*args, **kwargs2)
OperationalError: (1045, "Access denied for user '1bd3e0294da19198'@'localhost' (using password: YES)")

[DEBUG] 2017-05-24 07:02:37,290 | /Users/user/Documents/ERPNext-22-05-2017/frappe-bench/apps/frappe/frappe/utils/scheduler.py:
Site: site.local-development
Queued events for site site.local-development
[ERROR] 2017-05-24 07:02:37,292 | /Users/user/Documents/ERPNext-22-05-2017/frappe-bench/apps/frappe/frappe/utils/scheduler.py:
Site: site1.local
Exception in Enqueue Events for Site site1.local
Traceback (most recent call last):
  File "/Users/user/Documents/ERPNext-22-05-2017/frappe-bench/apps/frappe/frappe/utils/scheduler.py", line 63, in enqueue_events_for_site
    if is_scheduler_disabled():
  File "/Users/user/Documents/ERPNext-22-05-2017/frappe-bench/apps/frappe/frappe/utils/scheduler.py", line 207, in is_scheduler_disabled
    return not frappe.utils.cint(frappe.db.get_single_value("System Settings", "enable_scheduler"))
  File "/Users/user/Documents/ERPNext-22-05-2017/frappe-bench/apps/frappe/frappe/database.py", line 554, in get_single_value
    tabSingles where doctype=%s and field=%s""", (doctype, fieldname))
  File "/Users/user/Documents/ERPNext-22-05-2017/frappe-bench/apps/frappe/frappe/database.py", line 107, in sql
    self.connect()
  File "/Users/user/Documents/ERPNext-22-05-2017/frappe-bench/apps/frappe/frappe/database.py", line 53, in connect
    use_unicode=True, charset='utf8mb4')
  File "/Users/user/Documents/ERPNext-22-05-2017/frappe-bench/env/lib/python2.7/site-packages/MySQLdb/__init__.py", line 81, in Connect
    return Connection(*args, **kwargs)
  File "/Users/user/Documents/ERPNext-22-05-2017/frappe-bench/env/lib/python2.7/site-packages/MySQLdb/connections.py", line 193, in __init__
    super(Connection, self).__init__(*args, **kwargs2)
OperationalError: (1045, "Access denied for user '1bd3e0294da19198'@'localhost' (using password: YES)")

[DEBUG] 2017-05-24 07:07:11,113 | /Users/user/Documents/ERPNext-22-05-2017/frappe-bench/apps/frappe/frappe/utils/scheduler.py:
Site: site.local-development
Queued events for site site.local-development
[ERROR] 2017-05-24 07:07:11,116 | /Users/user/Documents/ERPNext-22-05-2017/frappe-bench/apps/frappe/frappe/utils/scheduler.py:
Site: site1.local
Exception in Enqueue Events for Site site1.local
Traceback (most recent call last):
  File "/Users/user/Documents/ERPNext-22-05-2017/frappe-bench/apps/frappe/frappe/utils/scheduler.py", line 63, in enqueue_events_for_site
    if is_scheduler_disabled():
  File "/Users/user/Documents/ERPNext-22-05-2017/frappe-bench/apps/frappe/frappe/utils/scheduler.py", line 207, in is_scheduler_disabled
    return not frappe.utils.cint(frappe.db.get_single_value("System Settings", "enable_scheduler"))
  File "/Users/user/Documents/ERPNext-22-05-2017/frappe-bench/apps/frappe/frappe/database.py", line 554, in get_single_value
    tabSingles where doctype=%s and field=%s""", (doctype, fieldname))
  File "/Users/user/Documents/ERPNext-22-05-2017/frappe-bench/apps/frappe/frappe/database.py", line 107, in sql
    self.connect()
  File "/Users/user/Documents/ERPNext-22-05-2017/frappe-bench/apps/frappe/frappe/database.py", line 53, in connect
    use_unicode=True, charset='utf8mb4')
  File "/Users/user/Documents/ERPNext-22-05-2017/frappe-bench/env/lib/python2.7/site-packages/MySQLdb/__init__.py", line 81, in Connect
    return Connection(*args, **kwargs)
  File "/Users/user/Documents/ERPNext-22-05-2017/frappe-bench/env/lib/python2.7/site-packages/MySQLdb/connections.py", line 193, in __init__
    super(Connection, self).__init__(*args, **kwargs2)
OperationalError: (1045, "Access denied for user '1bd3e0294da19198'@'localhost' (using password: YES)")

[ERROR] 2017-05-24 23:19:01,407 | /Users/user/Documents/ERPNext-22-05-2017/frappe-bench/apps/frappe/frappe/app.py:
Site: site.local-development
Form Dict: {
 "cmd": "frappe.utils.help.get_help", 
 "text": "pos"
}
Request Error
Traceback (most recent call last):
  File "/Users/user/Documents/ERPNext-22-05-2017/frappe-bench/apps/frappe/frappe/app.py", line 56, in application
    response = frappe.handler.handle()
  File "/Users/user/Documents/ERPNext-22-05-2017/frappe-bench/apps/frappe/frappe/handler.py", line 19, in handle
    execute_cmd(cmd)
  File "/Users/user/Documents/ERPNext-22-05-2017/frappe-bench/apps/frappe/frappe/handler.py", line 42, in execute_cmd
    ret = frappe.call(method, **frappe.form_dict)
  File "/Users/user/Documents/ERPNext-22-05-2017/frappe-bench/apps/frappe/frappe/__init__.py", line 907, in call
    return fn(*args, **newargs)
  File "/Users/user/Documents/ERPNext-22-05-2017/frappe-bench/apps/frappe/frappe/utils/help.py", line 29, in get_help
    return HelpDatabase().search(text)
  File "/Users/user/Documents/ERPNext-22-05-2017/frappe-bench/apps/frappe/frappe/utils/help.py", line 86, in search
    select title, intro, path from help where match(content) against (%s) limit 10''', ('%'+words+'%', words))
  File "/Users/user/Documents/ERPNext-22-05-2017/frappe-bench/apps/frappe/frappe/database.py", line 138, in sql
    self._cursor.execute(query, values)
  File "/Users/user/Documents/ERPNext-22-05-2017/frappe-bench/env/lib/python2.7/site-packages/MySQLdb/cursors.py", line 205, in execute
    self.errorhandler(self, exc, value)
  File "/Users/user/Documents/ERPNext-22-05-2017/frappe-bench/env/lib/python2.7/site-packages/MySQLdb/connections.py", line 36, in defaulterrorhandler
    raise errorclass, errorvalue
ProgrammingError: (1146, "Table 'erpnext-22.help' doesn't exist")
[ERROR] 2017-05-24 23:19:01,579 | /Users/user/Documents/ERPNext-22-05-2017/frappe-bench/apps/frappe/frappe/utils/error.py:
Could not take error snapshot: 'connection'
Traceback (most recent call last):
  File "/Users/user/Documents/ERPNext-22-05-2017/frappe-bench/apps/frappe/frappe/utils/error.py", line 36, in make_error_snapshot
    snapshot = get_snapshot(exception)
  File "/Users/user/Documents/ERPNext-22-05-2017/frappe-bench/apps/frappe/frappe/utils/error.py", line 81, in get_snapshot
    call = inspect.formatargvalues(args, varargs, varkw, locals, formatvalue=lambda value: '={}'.format(pydoc.text.repr(value)))
  File "/usr/local/Cellar/python/2.7.13/Frameworks/Python.framework/Versions/2.7/lib/python2.7/inspect.py", line 887, in formatargvalues
    specs.append(strseq(args[i], convert, join))
  File "/usr/local/Cellar/python/2.7.13/Frameworks/Python.framework/Versions/2.7/lib/python2.7/inspect.py", line 842, in strseq
    return convert(object)
  File "/usr/local/Cellar/python/2.7.13/Frameworks/Python.framework/Versions/2.7/lib/python2.7/inspect.py", line 884, in convert
    return formatarg(name) + formatvalue(locals[name])
KeyError: 'connection'
[ERROR] 2017-05-24 23:21:34,919 | /Users/user/Documents/ERPNext-22-05-2017/frappe-bench/apps/frappe/frappe/app.py:
Site: site.local-development
Form Dict: {
 "cmd": "frappe.utils.help.get_help", 
 "text": "pos"
}
Request Error
Traceback (most recent call last):
  File "/Users/user/Documents/ERPNext-22-05-2017/frappe-bench/apps/frappe/frappe/app.py", line 56, in application
    response = frappe.handler.handle()
  File "/Users/user/Documents/ERPNext-22-05-2017/frappe-bench/apps/frappe/frappe/handler.py", line 19, in handle
    execute_cmd(cmd)
  File "/Users/user/Documents/ERPNext-22-05-2017/frappe-bench/apps/frappe/frappe/handler.py", line 42, in execute_cmd
    ret = frappe.call(method, **frappe.form_dict)
  File "/Users/user/Documents/ERPNext-22-05-2017/frappe-bench/apps/frappe/frappe/__init__.py", line 907, in call
    return fn(*args, **newargs)
  File "/Users/user/Documents/ERPNext-22-05-2017/frappe-bench/apps/frappe/frappe/utils/help.py", line 29, in get_help
    return HelpDatabase().search(text)
  File "/Users/user/Documents/ERPNext-22-05-2017/frappe-bench/apps/frappe/frappe/utils/help.py", line 86, in search
    select title, intro, path from help where match(content) against (%s) limit 10''', ('%'+words+'%', words))
  File "/Users/user/Documents/ERPNext-22-05-2017/frappe-bench/apps/frappe/frappe/database.py", line 138, in sql
    self._cursor.execute(query, values)
  File "/Users/user/Documents/ERPNext-22-05-2017/frappe-bench/env/lib/python2.7/site-packages/MySQLdb/cursors.py", line 205, in execute
    self.errorhandler(self, exc, value)
  File "/Users/user/Documents/ERPNext-22-05-2017/frappe-bench/env/lib/python2.7/site-packages/MySQLdb/connections.py", line 36, in defaulterrorhandler
    raise errorclass, errorvalue
ProgrammingError: (1146, "Table 'erpnext-22.help' doesn't exist")
[ERROR] 2017-05-24 23:21:35,076 | /Users/user/Documents/ERPNext-22-05-2017/frappe-bench/apps/frappe/frappe/utils/error.py:
Could not take error snapshot: 'connection'
Traceback (most recent call last):
  File "/Users/user/Documents/ERPNext-22-05-2017/frappe-bench/apps/frappe/frappe/utils/error.py", line 36, in make_error_snapshot
    snapshot = get_snapshot(exception)
  File "/Users/user/Documents/ERPNext-22-05-2017/frappe-bench/apps/frappe/frappe/utils/error.py", line 81, in get_snapshot
    call = inspect.formatargvalues(args, varargs, varkw, locals, formatvalue=lambda value: '={}'.format(pydoc.text.repr(value)))
  File "/usr/local/Cellar/python/2.7.13/Frameworks/Python.framework/Versions/2.7/lib/python2.7/inspect.py", line 887, in formatargvalues
    specs.append(strseq(args[i], convert, join))
  File "/usr/local/Cellar/python/2.7.13/Frameworks/Python.framework/Versions/2.7/lib/python2.7/inspect.py", line 842, in strseq
    return convert(object)
  File "/usr/local/Cellar/python/2.7.13/Frameworks/Python.framework/Versions/2.7/lib/python2.7/inspect.py", line 884, in convert
    return formatarg(name) + formatvalue(locals[name])
KeyError: 'connection'
[DEBUG] 2017-05-24 23:40:44,220 | /Users/user/Documents/ERPNext-22-05-2017/frappe-bench/apps/frappe/frappe/utils/scheduler.py:
Site: site.local-development
Queued events for site site.local-development
[ERROR] 2017-05-24 23:40:44,225 | /Users/user/Documents/ERPNext-22-05-2017/frappe-bench/apps/frappe/frappe/utils/scheduler.py:
Site: site1.local
Exception in Enqueue Events for Site site1.local
Traceback (most recent call last):
  File "/Users/user/Documents/ERPNext-22-05-2017/frappe-bench/apps/frappe/frappe/utils/scheduler.py", line 63, in enqueue_events_for_site
    if is_scheduler_disabled():
  File "/Users/user/Documents/ERPNext-22-05-2017/frappe-bench/apps/frappe/frappe/utils/scheduler.py", line 207, in is_scheduler_disabled
    return not frappe.utils.cint(frappe.db.get_single_value("System Settings", "enable_scheduler"))
  File "/Users/user/Documents/ERPNext-22-05-2017/frappe-bench/apps/frappe/frappe/database.py", line 554, in get_single_value
    tabSingles where doctype=%s and field=%s""", (doctype, fieldname))
  File "/Users/user/Documents/ERPNext-22-05-2017/frappe-bench/apps/frappe/frappe/database.py", line 107, in sql
    self.connect()
  File "/Users/user/Documents/ERPNext-22-05-2017/frappe-bench/apps/frappe/frappe/database.py", line 53, in connect
    use_unicode=True, charset='utf8mb4')
  File "/Users/user/Documents/ERPNext-22-05-2017/frappe-bench/env/lib/python2.7/site-packages/MySQLdb/__init__.py", line 81, in Connect
    return Connection(*args, **kwargs)
  File "/Users/user/Documents/ERPNext-22-05-2017/frappe-bench/env/lib/python2.7/site-packages/MySQLdb/connections.py", line 193, in __init__
    super(Connection, self).__init__(*args, **kwargs2)
OperationalError: (1045, "Access denied for user '1bd3e0294da19198'@'localhost' (using password: YES)")

[DEBUG] 2017-05-24 23:46:13,765 | /Users/user/Documents/ERPNext-22-05-2017/frappe-bench/apps/frappe/frappe/utils/scheduler.py:
Site: site.local-development
Queued events for site site.local-development
[ERROR] 2017-05-24 23:46:13,770 | /Users/user/Documents/ERPNext-22-05-2017/frappe-bench/apps/frappe/frappe/utils/scheduler.py:
Site: site1.local
Exception in Enqueue Events for Site site1.local
Traceback (most recent call last):
  File "/Users/user/Documents/ERPNext-22-05-2017/frappe-bench/apps/frappe/frappe/utils/scheduler.py", line 63, in enqueue_events_for_site
    if is_scheduler_disabled():
  File "/Users/user/Documents/ERPNext-22-05-2017/frappe-bench/apps/frappe/frappe/utils/scheduler.py", line 207, in is_scheduler_disabled
    return not frappe.utils.cint(frappe.db.get_single_value("System Settings", "enable_scheduler"))
  File "/Users/user/Documents/ERPNext-22-05-2017/frappe-bench/apps/frappe/frappe/database.py", line 554, in get_single_value
    tabSingles where doctype=%s and field=%s""", (doctype, fieldname))
  File "/Users/user/Documents/ERPNext-22-05-2017/frappe-bench/apps/frappe/frappe/database.py", line 107, in sql
    self.connect()
  File "/Users/user/Documents/ERPNext-22-05-2017/frappe-bench/apps/frappe/frappe/database.py", line 53, in connect
    use_unicode=True, charset='utf8mb4')
  File "/Users/user/Documents/ERPNext-22-05-2017/frappe-bench/env/lib/python2.7/site-packages/MySQLdb/__init__.py", line 81, in Connect
    return Connection(*args, **kwargs)
  File "/Users/user/Documents/ERPNext-22-05-2017/frappe-bench/env/lib/python2.7/site-packages/MySQLdb/connections.py", line 193, in __init__
    super(Connection, self).__init__(*args, **kwargs2)
OperationalError: (1045, "Access denied for user '1bd3e0294da19198'@'localhost' (using password: YES)")

[DEBUG] 2017-05-24 23:50:14,386 | /Users/user/Documents/ERPNext-22-05-2017/frappe-bench/apps/frappe/frappe/utils/scheduler.py:
Site: site.local-development
Queued events for site site.local-development
[ERROR] 2017-05-24 23:50:14,388 | /Users/user/Documents/ERPNext-22-05-2017/frappe-bench/apps/frappe/frappe/utils/scheduler.py:
Site: site1.local
Exception in Enqueue Events for Site site1.local
Traceback (most recent call last):
  File "/Users/user/Documents/ERPNext-22-05-2017/frappe-bench/apps/frappe/frappe/utils/scheduler.py", line 63, in enqueue_events_for_site
    if is_scheduler_disabled():
  File "/Users/user/Documents/ERPNext-22-05-2017/frappe-bench/apps/frappe/frappe/utils/scheduler.py", line 207, in is_scheduler_disabled
    return not frappe.utils.cint(frappe.db.get_single_value("System Settings", "enable_scheduler"))
  File "/Users/user/Documents/ERPNext-22-05-2017/frappe-bench/apps/frappe/frappe/database.py", line 554, in get_single_value
    tabSingles where doctype=%s and field=%s""", (doctype, fieldname))
  File "/Users/user/Documents/ERPNext-22-05-2017/frappe-bench/apps/frappe/frappe/database.py", line 107, in sql
    self.connect()
  File "/Users/user/Documents/ERPNext-22-05-2017/frappe-bench/apps/frappe/frappe/database.py", line 53, in connect
    use_unicode=True, charset='utf8mb4')
  File "/Users/user/Documents/ERPNext-22-05-2017/frappe-bench/env/lib/python2.7/site-packages/MySQLdb/__init__.py", line 81, in Connect
    return Connection(*args, **kwargs)
  File "/Users/user/Documents/ERPNext-22-05-2017/frappe-bench/env/lib/python2.7/site-packages/MySQLdb/connections.py", line 193, in __init__
    super(Connection, self).__init__(*args, **kwargs2)
OperationalError: (1045, "Access denied for user '1bd3e0294da19198'@'localhost' (using password: YES)")

[DEBUG] 2017-05-24 23:54:15,006 | /Users/user/Documents/ERPNext-22-05-2017/frappe-bench/apps/frappe/frappe/utils/scheduler.py:
Site: site.local-development
Queued events for site site.local-development
[ERROR] 2017-05-24 23:54:15,008 | /Users/user/Documents/ERPNext-22-05-2017/frappe-bench/apps/frappe/frappe/utils/scheduler.py:
Site: site1.local
Exception in Enqueue Events for Site site1.local
Traceback (most recent call last):
  File "/Users/user/Documents/ERPNext-22-05-2017/frappe-bench/apps/frappe/frappe/utils/scheduler.py", line 63, in enqueue_events_for_site
    if is_scheduler_disabled():
  File "/Users/user/Documents/ERPNext-22-05-2017/frappe-bench/apps/frappe/frappe/utils/scheduler.py", line 207, in is_scheduler_disabled
    return not frappe.utils.cint(frappe.db.get_single_value("System Settings", "enable_scheduler"))
  File "/Users/user/Documents/ERPNext-22-05-2017/frappe-bench/apps/frappe/frappe/database.py", line 554, in get_single_value
    tabSingles where doctype=%s and field=%s""", (doctype, fieldname))
  File "/Users/user/Documents/ERPNext-22-05-2017/frappe-bench/apps/frappe/frappe/database.py", line 107, in sql
    self.connect()
  File "/Users/user/Documents/ERPNext-22-05-2017/frappe-bench/apps/frappe/frappe/database.py", line 53, in connect
    use_unicode=True, charset='utf8mb4')
  File "/Users/user/Documents/ERPNext-22-05-2017/frappe-bench/env/lib/python2.7/site-packages/MySQLdb/__init__.py", line 81, in Connect
    return Connection(*args, **kwargs)
  File "/Users/user/Documents/ERPNext-22-05-2017/frappe-bench/env/lib/python2.7/site-packages/MySQLdb/connections.py", line 193, in __init__
    super(Connection, self).__init__(*args, **kwargs2)
OperationalError: (1045, "Access denied for user '1bd3e0294da19198'@'localhost' (using password: YES)")

[DEBUG] 2017-05-24 23:58:15,355 | /Users/user/Documents/ERPNext-22-05-2017/frappe-bench/apps/frappe/frappe/utils/scheduler.py:
Site: site.local-development
Queued events for site site.local-development
[ERROR] 2017-05-24 23:58:15,357 | /Users/user/Documents/ERPNext-22-05-2017/frappe-bench/apps/frappe/frappe/utils/scheduler.py:
Site: site1.local
Exception in Enqueue Events for Site site1.local
Traceback (most recent call last):
  File "/Users/user/Documents/ERPNext-22-05-2017/frappe-bench/apps/frappe/frappe/utils/scheduler.py", line 63, in enqueue_events_for_site
    if is_scheduler_disabled():
  File "/Users/user/Documents/ERPNext-22-05-2017/frappe-bench/apps/frappe/frappe/utils/scheduler.py", line 207, in is_scheduler_disabled
    return not frappe.utils.cint(frappe.db.get_single_value("System Settings", "enable_scheduler"))
  File "/Users/user/Documents/ERPNext-22-05-2017/frappe-bench/apps/frappe/frappe/database.py", line 554, in get_single_value
    tabSingles where doctype=%s and field=%s""", (doctype, fieldname))
  File "/Users/user/Documents/ERPNext-22-05-2017/frappe-bench/apps/frappe/frappe/database.py", line 107, in sql
    self.connect()
  File "/Users/user/Documents/ERPNext-22-05-2017/frappe-bench/apps/frappe/frappe/database.py", line 53, in connect
    use_unicode=True, charset='utf8mb4')
  File "/Users/user/Documents/ERPNext-22-05-2017/frappe-bench/env/lib/python2.7/site-packages/MySQLdb/__init__.py", line 81, in Connect
    return Connection(*args, **kwargs)
  File "/Users/user/Documents/ERPNext-22-05-2017/frappe-bench/env/lib/python2.7/site-packages/MySQLdb/connections.py", line 193, in __init__
    super(Connection, self).__init__(*args, **kwargs2)
OperationalError: (1045, "Access denied for user '1bd3e0294da19198'@'localhost' (using password: YES)")

[DEBUG] 2017-05-25 00:09:43,622 | /Users/user/Documents/ERPNext-22-05-2017/frappe-bench/apps/frappe/frappe/utils/scheduler.py:
Site: site.local-development
Queued events for site site.local-development
[ERROR] 2017-05-25 00:09:43,627 | /Users/user/Documents/ERPNext-22-05-2017/frappe-bench/apps/frappe/frappe/utils/scheduler.py:
Site: site1.local
Exception in Enqueue Events for Site site1.local
Traceback (most recent call last):
  File "/Users/user/Documents/ERPNext-22-05-2017/frappe-bench/apps/frappe/frappe/utils/scheduler.py", line 63, in enqueue_events_for_site
    if is_scheduler_disabled():
  File "/Users/user/Documents/ERPNext-22-05-2017/frappe-bench/apps/frappe/frappe/utils/scheduler.py", line 207, in is_scheduler_disabled
    return not frappe.utils.cint(frappe.db.get_single_value("System Settings", "enable_scheduler"))
  File "/Users/user/Documents/ERPNext-22-05-2017/frappe-bench/apps/frappe/frappe/database.py", line 554, in get_single_value
    tabSingles where doctype=%s and field=%s""", (doctype, fieldname))
  File "/Users/user/Documents/ERPNext-22-05-2017/frappe-bench/apps/frappe/frappe/database.py", line 107, in sql
    self.connect()
  File "/Users/user/Documents/ERPNext-22-05-2017/frappe-bench/apps/frappe/frappe/database.py", line 53, in connect
    use_unicode=True, charset='utf8mb4')
  File "/Users/user/Documents/ERPNext-22-05-2017/frappe-bench/env/lib/python2.7/site-packages/MySQLdb/__init__.py", line 81, in Connect
    return Connection(*args, **kwargs)
  File "/Users/user/Documents/ERPNext-22-05-2017/frappe-bench/env/lib/python2.7/site-packages/MySQLdb/connections.py", line 193, in __init__
    super(Connection, self).__init__(*args, **kwargs2)
OperationalError: (1045, "Access denied for user '1bd3e0294da19198'@'localhost' (using password: YES)")

[DEBUG] 2017-05-25 00:13:44,313 | /Users/user/Documents/ERPNext-22-05-2017/frappe-bench/apps/frappe/frappe/utils/scheduler.py:
Site: site.local-development
Queued events for site site.local-development
[ERROR] 2017-05-25 00:13:44,315 | /Users/user/Documents/ERPNext-22-05-2017/frappe-bench/apps/frappe/frappe/utils/scheduler.py:
Site: site1.local
Exception in Enqueue Events for Site site1.local
Traceback (most recent call last):
  File "/Users/user/Documents/ERPNext-22-05-2017/frappe-bench/apps/frappe/frappe/utils/scheduler.py", line 63, in enqueue_events_for_site
    if is_scheduler_disabled():
  File "/Users/user/Documents/ERPNext-22-05-2017/frappe-bench/apps/frappe/frappe/utils/scheduler.py", line 207, in is_scheduler_disabled
    return not frappe.utils.cint(frappe.db.get_single_value("System Settings", "enable_scheduler"))
  File "/Users/user/Documents/ERPNext-22-05-2017/frappe-bench/apps/frappe/frappe/database.py", line 554, in get_single_value
    tabSingles where doctype=%s and field=%s""", (doctype, fieldname))
  File "/Users/user/Documents/ERPNext-22-05-2017/frappe-bench/apps/frappe/frappe/database.py", line 107, in sql
    self.connect()
  File "/Users/user/Documents/ERPNext-22-05-2017/frappe-bench/apps/frappe/frappe/database.py", line 53, in connect
    use_unicode=True, charset='utf8mb4')
  File "/Users/user/Documents/ERPNext-22-05-2017/frappe-bench/env/lib/python2.7/site-packages/MySQLdb/__init__.py", line 81, in Connect
    return Connection(*args, **kwargs)
  File "/Users/user/Documents/ERPNext-22-05-2017/frappe-bench/env/lib/python2.7/site-packages/MySQLdb/connections.py", line 193, in __init__
    super(Connection, self).__init__(*args, **kwargs2)
OperationalError: (1045, "Access denied for user '1bd3e0294da19198'@'localhost' (using password: YES)")

[DEBUG] 2017-05-25 00:17:45,150 | /Users/user/Documents/ERPNext-22-05-2017/frappe-bench/apps/frappe/frappe/utils/scheduler.py:
Site: site.local-development
Queued events for site site.local-development
[ERROR] 2017-05-25 00:17:45,152 | /Users/user/Documents/ERPNext-22-05-2017/frappe-bench/apps/frappe/frappe/utils/scheduler.py:
Site: site1.local
Exception in Enqueue Events for Site site1.local
Traceback (most recent call last):
  File "/Users/user/Documents/ERPNext-22-05-2017/frappe-bench/apps/frappe/frappe/utils/scheduler.py", line 63, in enqueue_events_for_site
    if is_scheduler_disabled():
  File "/Users/user/Documents/ERPNext-22-05-2017/frappe-bench/apps/frappe/frappe/utils/scheduler.py", line 207, in is_scheduler_disabled
    return not frappe.utils.cint(frappe.db.get_single_value("System Settings", "enable_scheduler"))
  File "/Users/user/Documents/ERPNext-22-05-2017/frappe-bench/apps/frappe/frappe/database.py", line 554, in get_single_value
    tabSingles where doctype=%s and field=%s""", (doctype, fieldname))
  File "/Users/user/Documents/ERPNext-22-05-2017/frappe-bench/apps/frappe/frappe/database.py", line 107, in sql
    self.connect()
  File "/Users/user/Documents/ERPNext-22-05-2017/frappe-bench/apps/frappe/frappe/database.py", line 53, in connect
    use_unicode=True, charset='utf8mb4')
  File "/Users/user/Documents/ERPNext-22-05-2017/frappe-bench/env/lib/python2.7/site-packages/MySQLdb/__init__.py", line 81, in Connect
    return Connection(*args, **kwargs)
  File "/Users/user/Documents/ERPNext-22-05-2017/frappe-bench/env/lib/python2.7/site-packages/MySQLdb/connections.py", line 193, in __init__
    super(Connection, self).__init__(*args, **kwargs2)
OperationalError: (1045, "Access denied for user '1bd3e0294da19198'@'localhost' (using password: YES)")

[DEBUG] 2017-05-25 00:21:45,665 | /Users/user/Documents/ERPNext-22-05-2017/frappe-bench/apps/frappe/frappe/utils/scheduler.py:
Site: site.local-development
Queued events for site site.local-development
[ERROR] 2017-05-25 00:21:45,667 | /Users/user/Documents/ERPNext-22-05-2017/frappe-bench/apps/frappe/frappe/utils/scheduler.py:
Site: site1.local
Exception in Enqueue Events for Site site1.local
Traceback (most recent call last):
  File "/Users/user/Documents/ERPNext-22-05-2017/frappe-bench/apps/frappe/frappe/utils/scheduler.py", line 63, in enqueue_events_for_site
    if is_scheduler_disabled():
  File "/Users/user/Documents/ERPNext-22-05-2017/frappe-bench/apps/frappe/frappe/utils/scheduler.py", line 207, in is_scheduler_disabled
    return not frappe.utils.cint(frappe.db.get_single_value("System Settings", "enable_scheduler"))
  File "/Users/user/Documents/ERPNext-22-05-2017/frappe-bench/apps/frappe/frappe/database.py", line 554, in get_single_value
    tabSingles where doctype=%s and field=%s""", (doctype, fieldname))
  File "/Users/user/Documents/ERPNext-22-05-2017/frappe-bench/apps/frappe/frappe/database.py", line 107, in sql
    self.connect()
  File "/Users/user/Documents/ERPNext-22-05-2017/frappe-bench/apps/frappe/frappe/database.py", line 53, in connect
    use_unicode=True, charset='utf8mb4')
  File "/Users/user/Documents/ERPNext-22-05-2017/frappe-bench/env/lib/python2.7/site-packages/MySQLdb/__init__.py", line 81, in Connect
    return Connection(*args, **kwargs)
  File "/Users/user/Documents/ERPNext-22-05-2017/frappe-bench/env/lib/python2.7/site-packages/MySQLdb/connections.py", line 193, in __init__
    super(Connection, self).__init__(*args, **kwargs2)
OperationalError: (1045, "Access denied for user '1bd3e0294da19198'@'localhost' (using password: YES)")

[ERROR] 2017-05-25 00:28:15,938 | /Users/user/Documents/ERPNext-22-05-2017/frappe-bench/apps/frappe/frappe/app.py:
Site: site.local-development
Form Dict: {
 "cmd": "frappe.utils.help.get_help", 
 "text": "pos"
}
Request Error
Traceback (most recent call last):
  File "/Users/user/Documents/ERPNext-22-05-2017/frappe-bench/apps/frappe/frappe/app.py", line 56, in application
    response = frappe.handler.handle()
  File "/Users/user/Documents/ERPNext-22-05-2017/frappe-bench/apps/frappe/frappe/handler.py", line 19, in handle
    execute_cmd(cmd)
  File "/Users/user/Documents/ERPNext-22-05-2017/frappe-bench/apps/frappe/frappe/handler.py", line 42, in execute_cmd
    ret = frappe.call(method, **frappe.form_dict)
  File "/Users/user/Documents/ERPNext-22-05-2017/frappe-bench/apps/frappe/frappe/__init__.py", line 907, in call
    return fn(*args, **newargs)
  File "/Users/user/Documents/ERPNext-22-05-2017/frappe-bench/apps/frappe/frappe/utils/help.py", line 29, in get_help
    return HelpDatabase().search(text)
  File "/Users/user/Documents/ERPNext-22-05-2017/frappe-bench/apps/frappe/frappe/utils/help.py", line 86, in search
    select title, intro, path from help where match(content) against (%s) limit 10''', ('%'+words+'%', words))
  File "/Users/user/Documents/ERPNext-22-05-2017/frappe-bench/apps/frappe/frappe/database.py", line 138, in sql
    self._cursor.execute(query, values)
  File "/Users/user/Documents/ERPNext-22-05-2017/frappe-bench/env/lib/python2.7/site-packages/MySQLdb/cursors.py", line 205, in execute
    self.errorhandler(self, exc, value)
  File "/Users/user/Documents/ERPNext-22-05-2017/frappe-bench/env/lib/python2.7/site-packages/MySQLdb/connections.py", line 36, in defaulterrorhandler
    raise errorclass, errorvalue
ProgrammingError: (1146, "Table 'erpnext-22.help' doesn't exist")
[ERROR] 2017-05-25 00:28:16,075 | /Users/user/Documents/ERPNext-22-05-2017/frappe-bench/apps/frappe/frappe/utils/error.py:
Could not take error snapshot: 'connection'
Traceback (most recent call last):
  File "/Users/user/Documents/ERPNext-22-05-2017/frappe-bench/apps/frappe/frappe/utils/error.py", line 36, in make_error_snapshot
    snapshot = get_snapshot(exception)
  File "/Users/user/Documents/ERPNext-22-05-2017/frappe-bench/apps/frappe/frappe/utils/error.py", line 81, in get_snapshot
    call = inspect.formatargvalues(args, varargs, varkw, locals, formatvalue=lambda value: '={}'.format(pydoc.text.repr(value)))
  File "/usr/local/Cellar/python/2.7.13/Frameworks/Python.framework/Versions/2.7/lib/python2.7/inspect.py", line 887, in formatargvalues
    specs.append(strseq(args[i], convert, join))
  File "/usr/local/Cellar/python/2.7.13/Frameworks/Python.framework/Versions/2.7/lib/python2.7/inspect.py", line 842, in strseq
    return convert(object)
  File "/usr/local/Cellar/python/2.7.13/Frameworks/Python.framework/Versions/2.7/lib/python2.7/inspect.py", line 884, in convert
    return formatarg(name) + formatvalue(locals[name])
KeyError: 'connection'
[DEBUG] 2017-05-25 00:29:39,803 | /Users/user/Documents/ERPNext-22-05-2017/frappe-bench/apps/frappe/frappe/utils/scheduler.py:
Site: site.local-development
Queued events for site site.local-development
[ERROR] 2017-05-25 00:29:39,807 | /Users/user/Documents/ERPNext-22-05-2017/frappe-bench/apps/frappe/frappe/utils/scheduler.py:
Site: site1.local
Exception in Enqueue Events for Site site1.local
Traceback (most recent call last):
  File "/Users/user/Documents/ERPNext-22-05-2017/frappe-bench/apps/frappe/frappe/utils/scheduler.py", line 63, in enqueue_events_for_site
    if is_scheduler_disabled():
  File "/Users/user/Documents/ERPNext-22-05-2017/frappe-bench/apps/frappe/frappe/utils/scheduler.py", line 207, in is_scheduler_disabled
    return not frappe.utils.cint(frappe.db.get_single_value("System Settings", "enable_scheduler"))
  File "/Users/user/Documents/ERPNext-22-05-2017/frappe-bench/apps/frappe/frappe/database.py", line 554, in get_single_value
    tabSingles where doctype=%s and field=%s""", (doctype, fieldname))
  File "/Users/user/Documents/ERPNext-22-05-2017/frappe-bench/apps/frappe/frappe/database.py", line 107, in sql
    self.connect()
  File "/Users/user/Documents/ERPNext-22-05-2017/frappe-bench/apps/frappe/frappe/database.py", line 53, in connect
    use_unicode=True, charset='utf8mb4')
  File "/Users/user/Documents/ERPNext-22-05-2017/frappe-bench/env/lib/python2.7/site-packages/MySQLdb/__init__.py", line 81, in Connect
    return Connection(*args, **kwargs)
  File "/Users/user/Documents/ERPNext-22-05-2017/frappe-bench/env/lib/python2.7/site-packages/MySQLdb/connections.py", line 193, in __init__
    super(Connection, self).__init__(*args, **kwargs2)
OperationalError: (1045, "Access denied for user '1bd3e0294da19198'@'localhost' (using password: YES)")

[DEBUG] 2017-05-25 00:33:40,773 | /Users/user/Documents/ERPNext-22-05-2017/frappe-bench/apps/frappe/frappe/utils/scheduler.py:
Site: site.local-development
Queued events for site site.local-development
[ERROR] 2017-05-25 00:33:40,775 | /Users/user/Documents/ERPNext-22-05-2017/frappe-bench/apps/frappe/frappe/utils/scheduler.py:
Site: site1.local
Exception in Enqueue Events for Site site1.local
Traceback (most recent call last):
  File "/Users/user/Documents/ERPNext-22-05-2017/frappe-bench/apps/frappe/frappe/utils/scheduler.py", line 63, in enqueue_events_for_site
    if is_scheduler_disabled():
  File "/Users/user/Documents/ERPNext-22-05-2017/frappe-bench/apps/frappe/frappe/utils/scheduler.py", line 207, in is_scheduler_disabled
    return not frappe.utils.cint(frappe.db.get_single_value("System Settings", "enable_scheduler"))
  File "/Users/user/Documents/ERPNext-22-05-2017/frappe-bench/apps/frappe/frappe/database.py", line 554, in get_single_value
    tabSingles where doctype=%s and field=%s""", (doctype, fieldname))
  File "/Users/user/Documents/ERPNext-22-05-2017/frappe-bench/apps/frappe/frappe/database.py", line 107, in sql
    self.connect()
  File "/Users/user/Documents/ERPNext-22-05-2017/frappe-bench/apps/frappe/frappe/database.py", line 53, in connect
    use_unicode=True, charset='utf8mb4')
  File "/Users/user/Documents/ERPNext-22-05-2017/frappe-bench/env/lib/python2.7/site-packages/MySQLdb/__init__.py", line 81, in Connect
    return Connection(*args, **kwargs)
  File "/Users/user/Documents/ERPNext-22-05-2017/frappe-bench/env/lib/python2.7/site-packages/MySQLdb/connections.py", line 193, in __init__
    super(Connection, self).__init__(*args, **kwargs2)
OperationalError: (1045, "Access denied for user '1bd3e0294da19198'@'localhost' (using password: YES)")

[DEBUG] 2017-05-25 00:37:41,869 | /Users/user/Documents/ERPNext-22-05-2017/frappe-bench/apps/frappe/frappe/utils/scheduler.py:
Site: site.local-development
Queued events for site site.local-development
[ERROR] 2017-05-25 00:37:41,871 | /Users/user/Documents/ERPNext-22-05-2017/frappe-bench/apps/frappe/frappe/utils/scheduler.py:
Site: site1.local
Exception in Enqueue Events for Site site1.local
Traceback (most recent call last):
  File "/Users/user/Documents/ERPNext-22-05-2017/frappe-bench/apps/frappe/frappe/utils/scheduler.py", line 63, in enqueue_events_for_site
    if is_scheduler_disabled():
  File "/Users/user/Documents/ERPNext-22-05-2017/frappe-bench/apps/frappe/frappe/utils/scheduler.py", line 207, in is_scheduler_disabled
    return not frappe.utils.cint(frappe.db.get_single_value("System Settings", "enable_scheduler"))
  File "/Users/user/Documents/ERPNext-22-05-2017/frappe-bench/apps/frappe/frappe/database.py", line 554, in get_single_value
    tabSingles where doctype=%s and field=%s""", (doctype, fieldname))
  File "/Users/user/Documents/ERPNext-22-05-2017/frappe-bench/apps/frappe/frappe/database.py", line 107, in sql
    self.connect()
  File "/Users/user/Documents/ERPNext-22-05-2017/frappe-bench/apps/frappe/frappe/database.py", line 53, in connect
    use_unicode=True, charset='utf8mb4')
  File "/Users/user/Documents/ERPNext-22-05-2017/frappe-bench/env/lib/python2.7/site-packages/MySQLdb/__init__.py", line 81, in Connect
    return Connection(*args, **kwargs)
  File "/Users/user/Documents/ERPNext-22-05-2017/frappe-bench/env/lib/python2.7/site-packages/MySQLdb/connections.py", line 193, in __init__
    super(Connection, self).__init__(*args, **kwargs2)
OperationalError: (1045, "Access denied for user '1bd3e0294da19198'@'localhost' (using password: YES)")

[DEBUG] 2017-05-25 00:41:42,741 | /Users/user/Documents/ERPNext-22-05-2017/frappe-bench/apps/frappe/frappe/utils/scheduler.py:
Site: site.local-development
Queued events for site site.local-development
[ERROR] 2017-05-25 00:41:42,743 | /Users/user/Documents/ERPNext-22-05-2017/frappe-bench/apps/frappe/frappe/utils/scheduler.py:
Site: site1.local
Exception in Enqueue Events for Site site1.local
Traceback (most recent call last):
  File "/Users/user/Documents/ERPNext-22-05-2017/frappe-bench/apps/frappe/frappe/utils/scheduler.py", line 63, in enqueue_events_for_site
    if is_scheduler_disabled():
  File "/Users/user/Documents/ERPNext-22-05-2017/frappe-bench/apps/frappe/frappe/utils/scheduler.py", line 207, in is_scheduler_disabled
    return not frappe.utils.cint(frappe.db.get_single_value("System Settings", "enable_scheduler"))
  File "/Users/user/Documents/ERPNext-22-05-2017/frappe-bench/apps/frappe/frappe/database.py", line 554, in get_single_value
    tabSingles where doctype=%s and field=%s""", (doctype, fieldname))
  File "/Users/user/Documents/ERPNext-22-05-2017/frappe-bench/apps/frappe/frappe/database.py", line 107, in sql
    self.connect()
  File "/Users/user/Documents/ERPNext-22-05-2017/frappe-bench/apps/frappe/frappe/database.py", line 53, in connect
    use_unicode=True, charset='utf8mb4')
  File "/Users/user/Documents/ERPNext-22-05-2017/frappe-bench/env/lib/python2.7/site-packages/MySQLdb/__init__.py", line 81, in Connect
    return Connection(*args, **kwargs)
  File "/Users/user/Documents/ERPNext-22-05-2017/frappe-bench/env/lib/python2.7/site-packages/MySQLdb/connections.py", line 193, in __init__
    super(Connection, self).__init__(*args, **kwargs2)
OperationalError: (1045, "Access denied for user '1bd3e0294da19198'@'localhost' (using password: YES)")

[DEBUG] 2017-05-25 00:45:43,666 | /Users/user/Documents/ERPNext-22-05-2017/frappe-bench/apps/frappe/frappe/utils/scheduler.py:
Site: site.local-development
Queued events for site site.local-development
[ERROR] 2017-05-25 00:45:43,670 | /Users/user/Documents/ERPNext-22-05-2017/frappe-bench/apps/frappe/frappe/utils/scheduler.py:
Site: site1.local
Exception in Enqueue Events for Site site1.local
Traceback (most recent call last):
  File "/Users/user/Documents/ERPNext-22-05-2017/frappe-bench/apps/frappe/frappe/utils/scheduler.py", line 63, in enqueue_events_for_site
    if is_scheduler_disabled():
  File "/Users/user/Documents/ERPNext-22-05-2017/frappe-bench/apps/frappe/frappe/utils/scheduler.py", line 207, in is_scheduler_disabled
    return not frappe.utils.cint(frappe.db.get_single_value("System Settings", "enable_scheduler"))
  File "/Users/user/Documents/ERPNext-22-05-2017/frappe-bench/apps/frappe/frappe/database.py", line 554, in get_single_value
    tabSingles where doctype=%s and field=%s""", (doctype, fieldname))
  File "/Users/user/Documents/ERPNext-22-05-2017/frappe-bench/apps/frappe/frappe/database.py", line 107, in sql
    self.connect()
  File "/Users/user/Documents/ERPNext-22-05-2017/frappe-bench/apps/frappe/frappe/database.py", line 53, in connect
    use_unicode=True, charset='utf8mb4')
  File "/Users/user/Documents/ERPNext-22-05-2017/frappe-bench/env/lib/python2.7/site-packages/MySQLdb/__init__.py", line 81, in Connect
    return Connection(*args, **kwargs)
  File "/Users/user/Documents/ERPNext-22-05-2017/frappe-bench/env/lib/python2.7/site-packages/MySQLdb/connections.py", line 193, in __init__
    super(Connection, self).__init__(*args, **kwargs2)
OperationalError: (1045, "Access denied for user '1bd3e0294da19198'@'localhost' (using password: YES)")

[DEBUG] 2017-05-25 00:49:44,432 | /Users/user/Documents/ERPNext-22-05-2017/frappe-bench/apps/frappe/frappe/utils/scheduler.py:
Site: site.local-development
Queued events for site site.local-development
[ERROR] 2017-05-25 00:49:44,435 | /Users/user/Documents/ERPNext-22-05-2017/frappe-bench/apps/frappe/frappe/utils/scheduler.py:
Site: site1.local
Exception in Enqueue Events for Site site1.local
Traceback (most recent call last):
  File "/Users/user/Documents/ERPNext-22-05-2017/frappe-bench/apps/frappe/frappe/utils/scheduler.py", line 63, in enqueue_events_for_site
    if is_scheduler_disabled():
  File "/Users/user/Documents/ERPNext-22-05-2017/frappe-bench/apps/frappe/frappe/utils/scheduler.py", line 207, in is_scheduler_disabled
    return not frappe.utils.cint(frappe.db.get_single_value("System Settings", "enable_scheduler"))
  File "/Users/user/Documents/ERPNext-22-05-2017/frappe-bench/apps/frappe/frappe/database.py", line 554, in get_single_value
    tabSingles where doctype=%s and field=%s""", (doctype, fieldname))
  File "/Users/user/Documents/ERPNext-22-05-2017/frappe-bench/apps/frappe/frappe/database.py", line 107, in sql
    self.connect()
  File "/Users/user/Documents/ERPNext-22-05-2017/frappe-bench/apps/frappe/frappe/database.py", line 53, in connect
    use_unicode=True, charset='utf8mb4')
  File "/Users/user/Documents/ERPNext-22-05-2017/frappe-bench/env/lib/python2.7/site-packages/MySQLdb/__init__.py", line 81, in Connect
    return Connection(*args, **kwargs)
  File "/Users/user/Documents/ERPNext-22-05-2017/frappe-bench/env/lib/python2.7/site-packages/MySQLdb/connections.py", line 193, in __init__
    super(Connection, self).__init__(*args, **kwargs2)
OperationalError: (1045, "Access denied for user '1bd3e0294da19198'@'localhost' (using password: YES)")

[DEBUG] 2017-05-25 04:00:46,693 | /Users/user/Documents/ERPNext-22-05-2017/frappe-bench/apps/frappe/frappe/utils/scheduler.py:
Site: site.local-development
Queued events for site site.local-development
[ERROR] 2017-05-25 04:00:46,698 | /Users/user/Documents/ERPNext-22-05-2017/frappe-bench/apps/frappe/frappe/utils/scheduler.py:
Site: site1.local
Exception in Enqueue Events for Site site1.local
Traceback (most recent call last):
  File "/Users/user/Documents/ERPNext-22-05-2017/frappe-bench/apps/frappe/frappe/utils/scheduler.py", line 63, in enqueue_events_for_site
    if is_scheduler_disabled():
  File "/Users/user/Documents/ERPNext-22-05-2017/frappe-bench/apps/frappe/frappe/utils/scheduler.py", line 207, in is_scheduler_disabled
    return not frappe.utils.cint(frappe.db.get_single_value("System Settings", "enable_scheduler"))
  File "/Users/user/Documents/ERPNext-22-05-2017/frappe-bench/apps/frappe/frappe/database.py", line 554, in get_single_value
    tabSingles where doctype=%s and field=%s""", (doctype, fieldname))
  File "/Users/user/Documents/ERPNext-22-05-2017/frappe-bench/apps/frappe/frappe/database.py", line 107, in sql
    self.connect()
  File "/Users/user/Documents/ERPNext-22-05-2017/frappe-bench/apps/frappe/frappe/database.py", line 53, in connect
    use_unicode=True, charset='utf8mb4')
  File "/Users/user/Documents/ERPNext-22-05-2017/frappe-bench/env/lib/python2.7/site-packages/MySQLdb/__init__.py", line 81, in Connect
    return Connection(*args, **kwargs)
  File "/Users/user/Documents/ERPNext-22-05-2017/frappe-bench/env/lib/python2.7/site-packages/MySQLdb/connections.py", line 193, in __init__
    super(Connection, self).__init__(*args, **kwargs2)
OperationalError: (1045, "Access denied for user '1bd3e0294da19198'@'localhost' (using password: YES)")

[DEBUG] 2017-05-25 04:04:47,415 | /Users/user/Documents/ERPNext-22-05-2017/frappe-bench/apps/frappe/frappe/utils/scheduler.py:
Site: site.local-development
Queued events for site site.local-development
[ERROR] 2017-05-25 04:04:47,417 | /Users/user/Documents/ERPNext-22-05-2017/frappe-bench/apps/frappe/frappe/utils/scheduler.py:
Site: site1.local
Exception in Enqueue Events for Site site1.local
Traceback (most recent call last):
  File "/Users/user/Documents/ERPNext-22-05-2017/frappe-bench/apps/frappe/frappe/utils/scheduler.py", line 63, in enqueue_events_for_site
    if is_scheduler_disabled():
  File "/Users/user/Documents/ERPNext-22-05-2017/frappe-bench/apps/frappe/frappe/utils/scheduler.py", line 207, in is_scheduler_disabled
    return not frappe.utils.cint(frappe.db.get_single_value("System Settings", "enable_scheduler"))
  File "/Users/user/Documents/ERPNext-22-05-2017/frappe-bench/apps/frappe/frappe/database.py", line 554, in get_single_value
    tabSingles where doctype=%s and field=%s""", (doctype, fieldname))
  File "/Users/user/Documents/ERPNext-22-05-2017/frappe-bench/apps/frappe/frappe/database.py", line 107, in sql
    self.connect()
  File "/Users/user/Documents/ERPNext-22-05-2017/frappe-bench/apps/frappe/frappe/database.py", line 53, in connect
    use_unicode=True, charset='utf8mb4')
  File "/Users/user/Documents/ERPNext-22-05-2017/frappe-bench/env/lib/python2.7/site-packages/MySQLdb/__init__.py", line 81, in Connect
    return Connection(*args, **kwargs)
  File "/Users/user/Documents/ERPNext-22-05-2017/frappe-bench/env/lib/python2.7/site-packages/MySQLdb/connections.py", line 193, in __init__
    super(Connection, self).__init__(*args, **kwargs2)
OperationalError: (1045, "Access denied for user '1bd3e0294da19198'@'localhost' (using password: YES)")

[DEBUG] 2017-05-25 04:08:48,181 | /Users/user/Documents/ERPNext-22-05-2017/frappe-bench/apps/frappe/frappe/utils/scheduler.py:
Site: site.local-development
Queued events for site site.local-development
[ERROR] 2017-05-25 04:08:48,183 | /Users/user/Documents/ERPNext-22-05-2017/frappe-bench/apps/frappe/frappe/utils/scheduler.py:
Site: site1.local
Exception in Enqueue Events for Site site1.local
Traceback (most recent call last):
  File "/Users/user/Documents/ERPNext-22-05-2017/frappe-bench/apps/frappe/frappe/utils/scheduler.py", line 63, in enqueue_events_for_site
    if is_scheduler_disabled():
  File "/Users/user/Documents/ERPNext-22-05-2017/frappe-bench/apps/frappe/frappe/utils/scheduler.py", line 207, in is_scheduler_disabled
    return not frappe.utils.cint(frappe.db.get_single_value("System Settings", "enable_scheduler"))
  File "/Users/user/Documents/ERPNext-22-05-2017/frappe-bench/apps/frappe/frappe/database.py", line 554, in get_single_value
    tabSingles where doctype=%s and field=%s""", (doctype, fieldname))
  File "/Users/user/Documents/ERPNext-22-05-2017/frappe-bench/apps/frappe/frappe/database.py", line 107, in sql
    self.connect()
  File "/Users/user/Documents/ERPNext-22-05-2017/frappe-bench/apps/frappe/frappe/database.py", line 53, in connect
    use_unicode=True, charset='utf8mb4')
  File "/Users/user/Documents/ERPNext-22-05-2017/frappe-bench/env/lib/python2.7/site-packages/MySQLdb/__init__.py", line 81, in Connect
    return Connection(*args, **kwargs)
  File "/Users/user/Documents/ERPNext-22-05-2017/frappe-bench/env/lib/python2.7/site-packages/MySQLdb/connections.py", line 193, in __init__
    super(Connection, self).__init__(*args, **kwargs2)
OperationalError: (1045, "Access denied for user '1bd3e0294da19198'@'localhost' (using password: YES)")

[DEBUG] 2017-05-25 04:17:09,804 | /Users/user/Documents/ERPNext-22-05-2017/frappe-bench/apps/frappe/frappe/utils/scheduler.py:
Site: site.local-development
Queued events for site site.local-development
[ERROR] 2017-05-25 04:17:09,814 | /Users/user/Documents/ERPNext-22-05-2017/frappe-bench/apps/frappe/frappe/utils/scheduler.py:
Site: site1.local
Exception in Enqueue Events for Site site1.local
Traceback (most recent call last):
  File "/Users/user/Documents/ERPNext-22-05-2017/frappe-bench/apps/frappe/frappe/utils/scheduler.py", line 63, in enqueue_events_for_site
    if is_scheduler_disabled():
  File "/Users/user/Documents/ERPNext-22-05-2017/frappe-bench/apps/frappe/frappe/utils/scheduler.py", line 207, in is_scheduler_disabled
    return not frappe.utils.cint(frappe.db.get_single_value("System Settings", "enable_scheduler"))
  File "/Users/user/Documents/ERPNext-22-05-2017/frappe-bench/apps/frappe/frappe/database.py", line 554, in get_single_value
    tabSingles where doctype=%s and field=%s""", (doctype, fieldname))
  File "/Users/user/Documents/ERPNext-22-05-2017/frappe-bench/apps/frappe/frappe/database.py", line 107, in sql
    self.connect()
  File "/Users/user/Documents/ERPNext-22-05-2017/frappe-bench/apps/frappe/frappe/database.py", line 53, in connect
    use_unicode=True, charset='utf8mb4')
  File "/Users/user/Documents/ERPNext-22-05-2017/frappe-bench/env/lib/python2.7/site-packages/MySQLdb/__init__.py", line 81, in Connect
    return Connection(*args, **kwargs)
  File "/Users/user/Documents/ERPNext-22-05-2017/frappe-bench/env/lib/python2.7/site-packages/MySQLdb/connections.py", line 193, in __init__
    super(Connection, self).__init__(*args, **kwargs2)
OperationalError: (1045, "Access denied for user '1bd3e0294da19198'@'localhost' (using password: YES)")

[DEBUG] 2017-05-25 04:23:04,986 | /Users/user/Documents/ERPNext-22-05-2017/frappe-bench/apps/frappe/frappe/utils/scheduler.py:
Site: site.local-development
Queued events for site site.local-development
[ERROR] 2017-05-25 04:23:04,990 | /Users/user/Documents/ERPNext-22-05-2017/frappe-bench/apps/frappe/frappe/utils/scheduler.py:
Site: site1.local
Exception in Enqueue Events for Site site1.local
Traceback (most recent call last):
  File "/Users/user/Documents/ERPNext-22-05-2017/frappe-bench/apps/frappe/frappe/utils/scheduler.py", line 63, in enqueue_events_for_site
    if is_scheduler_disabled():
  File "/Users/user/Documents/ERPNext-22-05-2017/frappe-bench/apps/frappe/frappe/utils/scheduler.py", line 207, in is_scheduler_disabled
    return not frappe.utils.cint(frappe.db.get_single_value("System Settings", "enable_scheduler"))
  File "/Users/user/Documents/ERPNext-22-05-2017/frappe-bench/apps/frappe/frappe/database.py", line 554, in get_single_value
    tabSingles where doctype=%s and field=%s""", (doctype, fieldname))
  File "/Users/user/Documents/ERPNext-22-05-2017/frappe-bench/apps/frappe/frappe/database.py", line 107, in sql
    self.connect()
  File "/Users/user/Documents/ERPNext-22-05-2017/frappe-bench/apps/frappe/frappe/database.py", line 53, in connect
    use_unicode=True, charset='utf8mb4')
  File "/Users/user/Documents/ERPNext-22-05-2017/frappe-bench/env/lib/python2.7/site-packages/MySQLdb/__init__.py", line 81, in Connect
    return Connection(*args, **kwargs)
  File "/Users/user/Documents/ERPNext-22-05-2017/frappe-bench/env/lib/python2.7/site-packages/MySQLdb/connections.py", line 193, in __init__
    super(Connection, self).__init__(*args, **kwargs2)
OperationalError: (1045, "Access denied for user '1bd3e0294da19198'@'localhost' (using password: YES)")

[DEBUG] 2017-05-25 04:27:05,894 | /Users/user/Documents/ERPNext-22-05-2017/frappe-bench/apps/frappe/frappe/utils/scheduler.py:
Site: site.local-development
Queued events for site site.local-development
[ERROR] 2017-05-25 04:27:05,899 | /Users/user/Documents/ERPNext-22-05-2017/frappe-bench/apps/frappe/frappe/utils/scheduler.py:
Site: site1.local
Exception in Enqueue Events for Site site1.local
Traceback (most recent call last):
  File "/Users/user/Documents/ERPNext-22-05-2017/frappe-bench/apps/frappe/frappe/utils/scheduler.py", line 63, in enqueue_events_for_site
    if is_scheduler_disabled():
  File "/Users/user/Documents/ERPNext-22-05-2017/frappe-bench/apps/frappe/frappe/utils/scheduler.py", line 207, in is_scheduler_disabled
    return not frappe.utils.cint(frappe.db.get_single_value("System Settings", "enable_scheduler"))
  File "/Users/user/Documents/ERPNext-22-05-2017/frappe-bench/apps/frappe/frappe/database.py", line 554, in get_single_value
    tabSingles where doctype=%s and field=%s""", (doctype, fieldname))
  File "/Users/user/Documents/ERPNext-22-05-2017/frappe-bench/apps/frappe/frappe/database.py", line 107, in sql
    self.connect()
  File "/Users/user/Documents/ERPNext-22-05-2017/frappe-bench/apps/frappe/frappe/database.py", line 53, in connect
    use_unicode=True, charset='utf8mb4')
  File "/Users/user/Documents/ERPNext-22-05-2017/frappe-bench/env/lib/python2.7/site-packages/MySQLdb/__init__.py", line 81, in Connect
    return Connection(*args, **kwargs)
  File "/Users/user/Documents/ERPNext-22-05-2017/frappe-bench/env/lib/python2.7/site-packages/MySQLdb/connections.py", line 193, in __init__
    super(Connection, self).__init__(*args, **kwargs2)
OperationalError: (1045, "Access denied for user '1bd3e0294da19198'@'localhost' (using password: YES)")

[DEBUG] 2017-05-25 04:31:06,792 | /Users/user/Documents/ERPNext-22-05-2017/frappe-bench/apps/frappe/frappe/utils/scheduler.py:
Site: site.local-development
Queued events for site site.local-development
[ERROR] 2017-05-25 04:31:06,804 | /Users/user/Documents/ERPNext-22-05-2017/frappe-bench/apps/frappe/frappe/utils/scheduler.py:
Site: site1.local
Exception in Enqueue Events for Site site1.local
Traceback (most recent call last):
  File "/Users/user/Documents/ERPNext-22-05-2017/frappe-bench/apps/frappe/frappe/utils/scheduler.py", line 63, in enqueue_events_for_site
    if is_scheduler_disabled():
  File "/Users/user/Documents/ERPNext-22-05-2017/frappe-bench/apps/frappe/frappe/utils/scheduler.py", line 207, in is_scheduler_disabled
    return not frappe.utils.cint(frappe.db.get_single_value("System Settings", "enable_scheduler"))
  File "/Users/user/Documents/ERPNext-22-05-2017/frappe-bench/apps/frappe/frappe/database.py", line 554, in get_single_value
    tabSingles where doctype=%s and field=%s""", (doctype, fieldname))
  File "/Users/user/Documents/ERPNext-22-05-2017/frappe-bench/apps/frappe/frappe/database.py", line 107, in sql
    self.connect()
  File "/Users/user/Documents/ERPNext-22-05-2017/frappe-bench/apps/frappe/frappe/database.py", line 53, in connect
    use_unicode=True, charset='utf8mb4')
  File "/Users/user/Documents/ERPNext-22-05-2017/frappe-bench/env/lib/python2.7/site-packages/MySQLdb/__init__.py", line 81, in Connect
    return Connection(*args, **kwargs)
  File "/Users/user/Documents/ERPNext-22-05-2017/frappe-bench/env/lib/python2.7/site-packages/MySQLdb/connections.py", line 193, in __init__
    super(Connection, self).__init__(*args, **kwargs2)
OperationalError: (1045, "Access denied for user '1bd3e0294da19198'@'localhost' (using password: YES)")

[DEBUG] 2017-05-25 04:35:07,535 | /Users/user/Documents/ERPNext-22-05-2017/frappe-bench/apps/frappe/frappe/utils/scheduler.py:
Site: site.local-development
Queued events for site site.local-development
[ERROR] 2017-05-25 04:35:07,537 | /Users/user/Documents/ERPNext-22-05-2017/frappe-bench/apps/frappe/frappe/utils/scheduler.py:
Site: site1.local
Exception in Enqueue Events for Site site1.local
Traceback (most recent call last):
  File "/Users/user/Documents/ERPNext-22-05-2017/frappe-bench/apps/frappe/frappe/utils/scheduler.py", line 63, in enqueue_events_for_site
    if is_scheduler_disabled():
  File "/Users/user/Documents/ERPNext-22-05-2017/frappe-bench/apps/frappe/frappe/utils/scheduler.py", line 207, in is_scheduler_disabled
    return not frappe.utils.cint(frappe.db.get_single_value("System Settings", "enable_scheduler"))
  File "/Users/user/Documents/ERPNext-22-05-2017/frappe-bench/apps/frappe/frappe/database.py", line 554, in get_single_value
    tabSingles where doctype=%s and field=%s""", (doctype, fieldname))
  File "/Users/user/Documents/ERPNext-22-05-2017/frappe-bench/apps/frappe/frappe/database.py", line 107, in sql
    self.connect()
  File "/Users/user/Documents/ERPNext-22-05-2017/frappe-bench/apps/frappe/frappe/database.py", line 53, in connect
    use_unicode=True, charset='utf8mb4')
  File "/Users/user/Documents/ERPNext-22-05-2017/frappe-bench/env/lib/python2.7/site-packages/MySQLdb/__init__.py", line 81, in Connect
    return Connection(*args, **kwargs)
  File "/Users/user/Documents/ERPNext-22-05-2017/frappe-bench/env/lib/python2.7/site-packages/MySQLdb/connections.py", line 193, in __init__
    super(Connection, self).__init__(*args, **kwargs2)
OperationalError: (1045, "Access denied for user '1bd3e0294da19198'@'localhost' (using password: YES)")

[DEBUG] 2017-05-25 04:39:08,223 | /Users/user/Documents/ERPNext-22-05-2017/frappe-bench/apps/frappe/frappe/utils/scheduler.py:
Site: site.local-development
Queued events for site site.local-development
[ERROR] 2017-05-25 04:39:08,226 | /Users/user/Documents/ERPNext-22-05-2017/frappe-bench/apps/frappe/frappe/utils/scheduler.py:
Site: site1.local
Exception in Enqueue Events for Site site1.local
Traceback (most recent call last):
  File "/Users/user/Documents/ERPNext-22-05-2017/frappe-bench/apps/frappe/frappe/utils/scheduler.py", line 63, in enqueue_events_for_site
    if is_scheduler_disabled():
  File "/Users/user/Documents/ERPNext-22-05-2017/frappe-bench/apps/frappe/frappe/utils/scheduler.py", line 207, in is_scheduler_disabled
    return not frappe.utils.cint(frappe.db.get_single_value("System Settings", "enable_scheduler"))
  File "/Users/user/Documents/ERPNext-22-05-2017/frappe-bench/apps/frappe/frappe/database.py", line 554, in get_single_value
    tabSingles where doctype=%s and field=%s""", (doctype, fieldname))
  File "/Users/user/Documents/ERPNext-22-05-2017/frappe-bench/apps/frappe/frappe/database.py", line 107, in sql
    self.connect()
  File "/Users/user/Documents/ERPNext-22-05-2017/frappe-bench/apps/frappe/frappe/database.py", line 53, in connect
    use_unicode=True, charset='utf8mb4')
  File "/Users/user/Documents/ERPNext-22-05-2017/frappe-bench/env/lib/python2.7/site-packages/MySQLdb/__init__.py", line 81, in Connect
    return Connection(*args, **kwargs)
  File "/Users/user/Documents/ERPNext-22-05-2017/frappe-bench/env/lib/python2.7/site-packages/MySQLdb/connections.py", line 193, in __init__
    super(Connection, self).__init__(*args, **kwargs2)
OperationalError: (1045, "Access denied for user '1bd3e0294da19198'@'localhost' (using password: YES)")

[ERROR] 2017-05-25 04:42:17,679 | /Users/user/Documents/ERPNext-22-05-2017/frappe-bench/apps/frappe/frappe/app.py:
Site: site.local-development
Form Dict: {
 "cmd": "frappe.desk.moduleview.get"
}
Request Error
Traceback (most recent call last):
  File "/Users/user/Documents/ERPNext-22-05-2017/frappe-bench/apps/frappe/frappe/app.py", line 56, in application
    response = frappe.handler.handle()
  File "/Users/user/Documents/ERPNext-22-05-2017/frappe-bench/apps/frappe/frappe/handler.py", line 19, in handle
    execute_cmd(cmd)
  File "/Users/user/Documents/ERPNext-22-05-2017/frappe-bench/apps/frappe/frappe/handler.py", line 42, in execute_cmd
    ret = frappe.call(method, **frappe.form_dict)
  File "/Users/user/Documents/ERPNext-22-05-2017/frappe-bench/apps/frappe/frappe/__init__.py", line 907, in call
    return fn(*args, **newargs)
TypeError: get() takes exactly 1 argument (0 given)
[ERROR] 2017-05-25 04:42:17,823 | /Users/user/Documents/ERPNext-22-05-2017/frappe-bench/apps/frappe/frappe/utils/error.py:
New Exception collected with id: 2017-05-25 04:42:17.680978-127.0.0.1-d22
[ERROR] 2017-05-25 04:42:40,715 | /Users/user/Documents/ERPNext-22-05-2017/frappe-bench/apps/frappe/frappe/app.py:
Site: site.local-development
Form Dict: {
 "cmd": "frappe.desk.moduleview.get"
}
Request Error
Traceback (most recent call last):
  File "/Users/user/Documents/ERPNext-22-05-2017/frappe-bench/apps/frappe/frappe/app.py", line 56, in application
    response = frappe.handler.handle()
  File "/Users/user/Documents/ERPNext-22-05-2017/frappe-bench/apps/frappe/frappe/handler.py", line 19, in handle
    execute_cmd(cmd)
  File "/Users/user/Documents/ERPNext-22-05-2017/frappe-bench/apps/frappe/frappe/handler.py", line 42, in execute_cmd
    ret = frappe.call(method, **frappe.form_dict)
  File "/Users/user/Documents/ERPNext-22-05-2017/frappe-bench/apps/frappe/frappe/__init__.py", line 907, in call
    return fn(*args, **newargs)
TypeError: get() takes exactly 1 argument (0 given)
[ERROR] 2017-05-25 04:42:40,718 | /Users/user/Documents/ERPNext-22-05-2017/frappe-bench/apps/frappe/frappe/utils/error.py:
New Exception collected with id: 2017-05-25 04:42:40.716150-127.0.0.1-d3b
[DEBUG] 2017-05-25 04:45:58,482 | /Users/user/Documents/ERPNext-22-05-2017/frappe-bench/apps/frappe/frappe/utils/scheduler.py:
Site: site.local-development
Queued events for site site.local-development
[ERROR] 2017-05-25 04:45:58,489 | /Users/user/Documents/ERPNext-22-05-2017/frappe-bench/apps/frappe/frappe/utils/scheduler.py:
Site: site1.local
Exception in Enqueue Events for Site site1.local
Traceback (most recent call last):
  File "/Users/user/Documents/ERPNext-22-05-2017/frappe-bench/apps/frappe/frappe/utils/scheduler.py", line 63, in enqueue_events_for_site
    if is_scheduler_disabled():
  File "/Users/user/Documents/ERPNext-22-05-2017/frappe-bench/apps/frappe/frappe/utils/scheduler.py", line 207, in is_scheduler_disabled
    return not frappe.utils.cint(frappe.db.get_single_value("System Settings", "enable_scheduler"))
  File "/Users/user/Documents/ERPNext-22-05-2017/frappe-bench/apps/frappe/frappe/database.py", line 554, in get_single_value
    tabSingles where doctype=%s and field=%s""", (doctype, fieldname))
  File "/Users/user/Documents/ERPNext-22-05-2017/frappe-bench/apps/frappe/frappe/database.py", line 107, in sql
    self.connect()
  File "/Users/user/Documents/ERPNext-22-05-2017/frappe-bench/apps/frappe/frappe/database.py", line 53, in connect
    use_unicode=True, charset='utf8mb4')
  File "/Users/user/Documents/ERPNext-22-05-2017/frappe-bench/env/lib/python2.7/site-packages/MySQLdb/__init__.py", line 81, in Connect
    return Connection(*args, **kwargs)
  File "/Users/user/Documents/ERPNext-22-05-2017/frappe-bench/env/lib/python2.7/site-packages/MySQLdb/connections.py", line 193, in __init__
    super(Connection, self).__init__(*args, **kwargs2)
OperationalError: (1045, "Access denied for user '1bd3e0294da19198'@'localhost' (using password: YES)")

[DEBUG] 2017-05-25 04:50:29,789 | /Users/user/Documents/ERPNext-22-05-2017/frappe-bench/apps/frappe/frappe/utils/scheduler.py:
Site: site.local-development
Queued events for site site.local-development
[ERROR] 2017-05-25 04:50:29,794 | /Users/user/Documents/ERPNext-22-05-2017/frappe-bench/apps/frappe/frappe/utils/scheduler.py:
Site: site1.local
Exception in Enqueue Events for Site site1.local
Traceback (most recent call last):
  File "/Users/user/Documents/ERPNext-22-05-2017/frappe-bench/apps/frappe/frappe/utils/scheduler.py", line 63, in enqueue_events_for_site
    if is_scheduler_disabled():
  File "/Users/user/Documents/ERPNext-22-05-2017/frappe-bench/apps/frappe/frappe/utils/scheduler.py", line 207, in is_scheduler_disabled
    return not frappe.utils.cint(frappe.db.get_single_value("System Settings", "enable_scheduler"))
  File "/Users/user/Documents/ERPNext-22-05-2017/frappe-bench/apps/frappe/frappe/database.py", line 554, in get_single_value
    tabSingles where doctype=%s and field=%s""", (doctype, fieldname))
  File "/Users/user/Documents/ERPNext-22-05-2017/frappe-bench/apps/frappe/frappe/database.py", line 107, in sql
    self.connect()
  File "/Users/user/Documents/ERPNext-22-05-2017/frappe-bench/apps/frappe/frappe/database.py", line 53, in connect
    use_unicode=True, charset='utf8mb4')
  File "/Users/user/Documents/ERPNext-22-05-2017/frappe-bench/env/lib/python2.7/site-packages/MySQLdb/__init__.py", line 81, in Connect
    return Connection(*args, **kwargs)
  File "/Users/user/Documents/ERPNext-22-05-2017/frappe-bench/env/lib/python2.7/site-packages/MySQLdb/connections.py", line 193, in __init__
    super(Connection, self).__init__(*args, **kwargs2)
OperationalError: (1045, "Access denied for user '1bd3e0294da19198'@'localhost' (using password: YES)")

[DEBUG] 2017-05-25 04:54:40,682 | /Users/user/Documents/ERPNext-22-05-2017/frappe-bench/apps/frappe/frappe/utils/scheduler.py:
Site: site.local-development
Queued events for site site.local-development
[ERROR] 2017-05-25 04:54:40,688 | /Users/user/Documents/ERPNext-22-05-2017/frappe-bench/apps/frappe/frappe/utils/scheduler.py:
Site: site1.local
Exception in Enqueue Events for Site site1.local
Traceback (most recent call last):
  File "/Users/user/Documents/ERPNext-22-05-2017/frappe-bench/apps/frappe/frappe/utils/scheduler.py", line 63, in enqueue_events_for_site
    if is_scheduler_disabled():
  File "/Users/user/Documents/ERPNext-22-05-2017/frappe-bench/apps/frappe/frappe/utils/scheduler.py", line 207, in is_scheduler_disabled
    return not frappe.utils.cint(frappe.db.get_single_value("System Settings", "enable_scheduler"))
  File "/Users/user/Documents/ERPNext-22-05-2017/frappe-bench/apps/frappe/frappe/database.py", line 554, in get_single_value
    tabSingles where doctype=%s and field=%s""", (doctype, fieldname))
  File "/Users/user/Documents/ERPNext-22-05-2017/frappe-bench/apps/frappe/frappe/database.py", line 107, in sql
    self.connect()
  File "/Users/user/Documents/ERPNext-22-05-2017/frappe-bench/apps/frappe/frappe/database.py", line 53, in connect
    use_unicode=True, charset='utf8mb4')
  File "/Users/user/Documents/ERPNext-22-05-2017/frappe-bench/env/lib/python2.7/site-packages/MySQLdb/__init__.py", line 81, in Connect
    return Connection(*args, **kwargs)
  File "/Users/user/Documents/ERPNext-22-05-2017/frappe-bench/env/lib/python2.7/site-packages/MySQLdb/connections.py", line 193, in __init__
    super(Connection, self).__init__(*args, **kwargs2)
OperationalError: (1045, "Access denied for user '1bd3e0294da19198'@'localhost' (using password: YES)")

[DEBUG] 2017-05-25 04:58:41,667 | /Users/user/Documents/ERPNext-22-05-2017/frappe-bench/apps/frappe/frappe/utils/scheduler.py:
Site: site.local-development
Queued events for site site.local-development
[ERROR] 2017-05-25 04:58:41,668 | /Users/user/Documents/ERPNext-22-05-2017/frappe-bench/apps/frappe/frappe/utils/scheduler.py:
Site: site1.local
Exception in Enqueue Events for Site site1.local
Traceback (most recent call last):
  File "/Users/user/Documents/ERPNext-22-05-2017/frappe-bench/apps/frappe/frappe/utils/scheduler.py", line 63, in enqueue_events_for_site
    if is_scheduler_disabled():
  File "/Users/user/Documents/ERPNext-22-05-2017/frappe-bench/apps/frappe/frappe/utils/scheduler.py", line 207, in is_scheduler_disabled
    return not frappe.utils.cint(frappe.db.get_single_value("System Settings", "enable_scheduler"))
  File "/Users/user/Documents/ERPNext-22-05-2017/frappe-bench/apps/frappe/frappe/database.py", line 554, in get_single_value
    tabSingles where doctype=%s and field=%s""", (doctype, fieldname))
  File "/Users/user/Documents/ERPNext-22-05-2017/frappe-bench/apps/frappe/frappe/database.py", line 107, in sql
    self.connect()
  File "/Users/user/Documents/ERPNext-22-05-2017/frappe-bench/apps/frappe/frappe/database.py", line 53, in connect
    use_unicode=True, charset='utf8mb4')
  File "/Users/user/Documents/ERPNext-22-05-2017/frappe-bench/env/lib/python2.7/site-packages/MySQLdb/__init__.py", line 81, in Connect
    return Connection(*args, **kwargs)
  File "/Users/user/Documents/ERPNext-22-05-2017/frappe-bench/env/lib/python2.7/site-packages/MySQLdb/connections.py", line 193, in __init__
    super(Connection, self).__init__(*args, **kwargs2)
OperationalError: (1045, "Access denied for user '1bd3e0294da19198'@'localhost' (using password: YES)")

[DEBUG] 2017-05-25 05:02:42,529 | /Users/user/Documents/ERPNext-22-05-2017/frappe-bench/apps/frappe/frappe/utils/scheduler.py:
Site: site.local-development
Queued events for site site.local-development
[ERROR] 2017-05-25 05:02:42,531 | /Users/user/Documents/ERPNext-22-05-2017/frappe-bench/apps/frappe/frappe/utils/scheduler.py:
Site: site1.local
Exception in Enqueue Events for Site site1.local
Traceback (most recent call last):
  File "/Users/user/Documents/ERPNext-22-05-2017/frappe-bench/apps/frappe/frappe/utils/scheduler.py", line 63, in enqueue_events_for_site
    if is_scheduler_disabled():
  File "/Users/user/Documents/ERPNext-22-05-2017/frappe-bench/apps/frappe/frappe/utils/scheduler.py", line 207, in is_scheduler_disabled
    return not frappe.utils.cint(frappe.db.get_single_value("System Settings", "enable_scheduler"))
  File "/Users/user/Documents/ERPNext-22-05-2017/frappe-bench/apps/frappe/frappe/database.py", line 554, in get_single_value
    tabSingles where doctype=%s and field=%s""", (doctype, fieldname))
  File "/Users/user/Documents/ERPNext-22-05-2017/frappe-bench/apps/frappe/frappe/database.py", line 107, in sql
    self.connect()
  File "/Users/user/Documents/ERPNext-22-05-2017/frappe-bench/apps/frappe/frappe/database.py", line 53, in connect
    use_unicode=True, charset='utf8mb4')
  File "/Users/user/Documents/ERPNext-22-05-2017/frappe-bench/env/lib/python2.7/site-packages/MySQLdb/__init__.py", line 81, in Connect
    return Connection(*args, **kwargs)
  File "/Users/user/Documents/ERPNext-22-05-2017/frappe-bench/env/lib/python2.7/site-packages/MySQLdb/connections.py", line 193, in __init__
    super(Connection, self).__init__(*args, **kwargs2)
OperationalError: (1045, "Access denied for user '1bd3e0294da19198'@'localhost' (using password: YES)")

[DEBUG] 2017-05-25 05:06:43,560 | /Users/user/Documents/ERPNext-22-05-2017/frappe-bench/apps/frappe/frappe/utils/scheduler.py:
Site: site.local-development
Queued events for site site.local-development
